Workbook

Sheet Zbiorczy
A1: =Karta!A2 | B1: =Karta!B2 | C1: =Karta!C2 | D1: =Karta!D2 | E1: =Karta!E2 | F1: =Karta!F2 | G1: =Karta!G2 | H1: =Karta!H2 | ... AB1: =Karta!AB2 | AC1: =Karta!AG2 | AD1: =Karta!AH2 | AE1: =Karta!AI2 | AF1: =Karta!AJ2 | AG1: =Karta!AL2 | AH1: =Karta!AM2 | AI1: =Karta!AN2 | AJ1: =Karta!AO2 | AK1: =Karta!AP2 | AL1: =Karta!AQ2 | AM1: =Karta!AR2 | AN1: =Karta!AS2 | ... AS1: =Karta!AX2 | AT1: =Karta!BC2 | AU1: =Karta!BD2 | AV1: =Karta!BE2 | AW1: =Karta!BF2 | AX1: =Karta!BH2 | AY1: =Karta!BI2 | AZ1: =Karta!BJ2 | BA1: =Karta!BK2 | BB1: =Karta!BL2 | BC1: =Karta!BM2 | BD1: =Karta!BN2 | BE1: =Karta!BO2 | ... CE1: =Karta!CO2
A2: 0 | B2: 0 | C2: 0 | D2: 0 | E2: HARMONOGRAM SKOMPRESOWANY v1 | 01.01.2027 – 28.09.2029 | Kompresja −40% per zadanie | Endava +5 etatów | AGH +4 etatów | F2: 0 | G2: 0 | H2: 0 | I2: 0 | J2: 0 | K2: 0 | L2: 0 | M2: 0 | N2: 0 | O2: =SUM(O101:O1300) | P2: 0 | Q2: 0 | R2: 0 | S2: 0 | T2: 0 | U2: 0 | V2: 0 | W2: 0 | X2: 0 | Y2: 0 | Z2: 0 | AA2: 0 | AB2: 0 | AC2: 0 | AD2: 0 | AE2: 0 | AF2: 0 | AG2: =SUM(AG101:AG1300) | AH2: =SUM(AH101:AH1300) | AI2: =SUM(AI101:AI1300) | AJ2: =SUM(AJ101:AJ1300) | AK2: =SUM(AK101:AK1300) | AL2: =SUM(AL101:AL1300) | AM2: =SUM(AM101:AM1300) | AN2: =SUM(AN101:AN1300) | ... AW2: =SUM(AW101:AW1300) | AX2: 0 | AY2: 0 | AZ2: 0 | BA2: 0 | BB2: 0 | BC2: 0 | BD2: 0 | BE2: 0 | BF2: 0 | BG2: 0 | BH2: 0 | BI2: 0 | BJ2: 0 | BK2: 0 | BL2: 0 | BM2: 0 | BN2: 0 | BO2: 0 | BP2: 0 | BQ2: 0 | BR2: 0 | BS2: 0 | BT2: 0 | BU2: 0 | BV2: 0 | BW2: 0 | BX2: 0 | BY2: 0 | BZ2: 0 | CA2: 0 | CB2: 0 | CC2: 0 | CD2: 0 | CE2: 0
A3: 0 | B3: 0 | C3: 0 | D3: 0 | E3: 0 | F3: 0 | G3: 0 | H3: 0 | I3: 0 | J3: 0 | K3: 0 | L3: 0 | M3: 0 | N3: 0 | O3: =SUM(AG2:AW2) | P3: 0 | Q3: 0 | R3: 0 | S3: 0 | T3: 0 | U3: 0 | V3: 0 | W3: 0 | X3: 0 | Y3: 0 | Z3: 0 | AA3: 0 | AB3: 0 | AC3: 0 | AD3: 0 | AE3: 0 | AF3: 0 | AG3: 0 | AH3: 0 | AI3: 0 | AJ3: 0 | AK3: 0 | AL3: 0 | AM3: 0 | AN3: 0 | AO3: 0 | AP3: 0 | AQ3: 0 | AR3: 0 | AS3: 0 | AT3: 0 | AU3: 0 | AV3: 0 | AW3: 0 | AX3: 0 | AY3: 0 | AZ3: 0 | BA3: 0 | BB3: 0 | BC3: 0 | BD3: 0 | BE3: 0 | BF3: 0 | BG3: 0 | BH3: 0 | BI3: 0 | BJ3: 0 | BK3: 0 | BL3: 0 | BM3: 0 | BN3: 0 | BO3: 0 | BP3: 0 | BQ3: 0 | BR3: 0 | BS3: 0 | BT3: 0 | BU3: 0 | BV3: 0 | BW3: 0 | BX3: 0 | BY3: 0 | BZ3: 0 | CA3: 0 | CB3: 0 | CC3: 0 | CD3: 0 | CE3: 0
A4: 0 | B4: 0 | C4: 0 | D4: 0 | E4: 0 | F4: 0 | G4: 0 | H4: 0 | I4: 0 | J4: 0 | K4: 0 | L4: 0 | M4: 0 | N4: 0 | O4: =O2-O3 | P4: 0 | Q4: 0 | R4: 0 | S4: 0 | T4: 0 | U4: 0 | V4: 0 | W4: 0 | X4: 0 | Y4: 0 | Z4: 0 | AA4: 0 | AB4: 0 | AC4: 0 | AD4: 0 | AE4: 0 | AF4: 0 | AG4: 0 | AH4: 0 | AI4: 0 | AJ4: 0 | AK4: 0 | AL4: 0 | AM4: 0 | AN4: 0 | AO4: 0 | AP4: 0 | AQ4: 0 | AR4: 0 | AS4: 0 | AT4: 0 | AU4: 0 | AV4: 0 | AW4: 0 | AX4: 0 | AY4: 0 | AZ4: 0 | BA4: 0 | BB4: 0 | BC4: 0 | BD4: 0 | BE4: 0 | BF4: 0 | BG4: 0 | BH4: 0 | BI4: 0 | BJ4: 0 | BK4: 0 | BL4: 0 | BM4: 0 | BN4: 0 | BO4: 0 | BP4: 0 | BQ4: 0 | BR4: 0 | BS4: 0 | BT4: 0 | BU4: 0 | BV4: 0 | BW4: 0 | BX4: 0 | BY4: 0 | BZ4: 0 | CA4: 0 | CB4: 0 | CC4: 0 | CD4: 0 | CE4: 0
A5: 0 | B5: 0 | C5: 0 | D5: 0 | E5: 0 | F5: 0 | G5: 0 | H5: 0 | I5: 0 | J5: 0 | K5: 0 | L5: 0 | M5: 0 | N5: 0 | O5: 0 | P5: 0 | Q5: 0 | R5: 0 | S5: 0 | T5: 0 | U5: 0 | V5: 0 | W5: 0 | X5: 0 | Y5: 0 | Z5: 0 | AA5: 0 | AB5: 0 | AC5: 0 | AD5: 0 | AE5: 0 | AF5: 0 | AG5: 0 | AH5: 0 | AI5: 0 | AJ5: 0 | AK5: 0 | AL5: 0 | AM5: 0 | AN5: 0 | AO5: 0 | AP5: 0 | AQ5: 0 | AR5: 0 | AS5: 0 | AT5: 0 | AU5: 0 | AV5: 0 | AW5: 0 | AX5: 0 | AY5: 0 | AZ5: 0 | BA5: 0 | BB5: 0 | BC5: 0 | BD5: 0 | BE5: 0 | BF5: 0 | BG5: 0 | BH5: 0 | BI5: 0 | BJ5: 0 | BK5: 0 | BL5: 0 | BM5: 0 | BN5: 0 | BO5: 0 | BP5: 0 | BQ5: 0 | BR5: 0 | BS5: 0 | BT5: 0 | BU5: 0 | BV5: 0 | BW5: 0 | BX5: 0 | BY5: 0 | BZ5: 0 | CA5: 0 | CB5: 0 | CC5: 0 | CD5: 0 | CE5: 0
A6: 0 | B6: 0 | C6: 0 | D6: 0 | E6: 0 | F6: 0 | G6: 0 | H6: 0 | I6: 0 | J6: 0 | K6: 0 | L6: 0 | M6: 0 | N6: 0 | O6: 0 | P6: 0 | Q6: 0 | R6: 0 | S6: 0 | T6: 0 | U6: 0 | V6: 0 | W6: 0 | X6: 0 | Y6: 0 | Z6: 0 | AA6: 0 | AB6: 0 | AC6: 0 | AD6: 0 | AE6: 0 | AF6: 0 | AG6: 0 | AH6: 0 | AI6: 0 | AJ6: 0 | AK6: 0 | AL6: 0 | AM6: 0 | AN6: 0 | AO6: 0 | AP6: 0 | AQ6: 0 | AR6: 0 | AS6: 0 | AT6: 0 | AU6: 0 | AV6: 0 | AW6: 0 | AX6: 0 | AY6: 0 | AZ6: 0 | BA6: 0 | BB6: 0 | BC6: 0 | BD6: 0 | BE6: 0 | BF6: 0 | BG6: 0 | BH6: 0 | BI6: 0 | BJ6: 0 | BK6: 0 | BL6: 0 | BM6: 0 | BN6: 0 | BO6: 0 | BP6: 0 | BQ6: 0 | BR6: 0 | BS6: 0 | BT6: 0 | BU6: 0 | BV6: 0 | BW6: 0 | BX6: 0 | BY6: 0 | BZ6: 0 | CA6: 0 | CB6: 0 | CC6: 0 | CD6: 0 | CE6: 0
A7: 0 | B7: 0 | C7: 0 | D7: 0 | E7: 0 | F7: 0 | G7: 0 | H7: 0 | I7: 0 | J7: 0 | K7: 0 | L7: 0 | M7: 0 | N7: 0 | O7: 0 | P7: 0 | Q7: 0 | R7: 0 | S7: 0 | T7: 0 | U7: 0 | V7: 0 | W7: 0 | X7: 0 | Y7: 0 | Z7: 0 | AA7: 0 | AB7: 0 | AC7: 0 | AD7: 0 | AE7: 0 | AF7: 0 | AG7: 0 | AH7: 0 | AI7: 0 | AJ7: 0 | AK7: 0 | AL7: 0 | AM7: 0 | AN7: 0 | AO7: 0 | AP7: 0 | AQ7: 0 | AR7: 0 | AS7: 0 | AT7: 0 | AU7: 0 | AV7: 0 | AW7: 0 | AX7: 0 | AY7: 0 | AZ7: 0 | BA7: 0 | BB7: 0 | BC7: 0 | BD7: 0 | BE7: 0 | BF7: 0 | BG7: 0 | BH7: 0 | BI7: 0 | BJ7: 0 | BK7: 0 | BL7: 0 | BM7: 0 | BN7: 0 | BO7: 0 | BP7: 0 | BQ7: 0 | BR7: 0 | BS7: 0 | BT7: 0 | BU7: 0 | BV7: 0 | BW7: 0 | BX7: 0 | BY7: 0 | BZ7: 0 | CA7: 0 | CB7: 0 | CC7: 0 | CD7: 0 | CE7: 0
A8: 0 | B8: 0 | C8: 0 | D8: 0 | E8: 0 | F8: 0 | G8: 0 | H8: 0 | I8: 0 | J8: 0 | K8: 0 | L8: 0 | M8: 0 | N8: 0 | O8: 0 | P8: 0 | Q8: 0 | R8: 0 | S8: 0 | T8: 0 | U8: 0 | V8: 0 | W8: 0 | X8: 0 | Y8: 0 | Z8: 0 | AA8: 0 | AB8: 0 | AC8: 0 | AD8: 0 | AE8: 0 | AF8: 0 | AG8: 0 | AH8: 0 | AI8: 0 | AJ8: 0 | AK8: 0 | AL8: 0 | AM8: 0 | AN8: 0 | AO8: 0 | AP8: 0 | AQ8: 0 | AR8: 0 | AS8: 0 | AT8: 0 | AU8: 0 | AV8: 0 | AW8: 0 | AX8: 0 | AY8: 0 | AZ8: 0 | BA8: 0 | BB8: 0 | BC8: 0 | BD8: 0 | BE8: 0 | BF8: 0 | BG8: 0 | BH8: 0 | BI8: 0 | BJ8: 0 | BK8: 0 | BL8: 0 | BM8: 0 | BN8: 0 | BO8: 0 | BP8: 0 | BQ8: 0 | BR8: 0 | BS8: 0 | BT8: 0 | BU8: 0 | BV8: 0 | BW8: 0 | BX8: 0 | BY8: 0 | BZ8: 0 | CA8: 0 | CB8: 0 | CC8: 0 | CD8: 0 | CE8: 0
A9: 0 | B9: 0 | C9: 0 | D9: 0 | E9: 0 | F9: 0 | G9: 0 | H9: 0 | I9: 0 | J9: 0 | K9: 0 | L9: 0 | M9: 0 | N9: 0 | O9: 0 | P9: 0 | Q9: 0 | R9: 0 | S9: 0 | T9: 0 | U9: 0 | V9: 0 | W9: 0 | X9: 0 | Y9: 0 | Z9: 0 | AA9: 0 | AB9: 0 | AC9: 0 | AD9: 0 | AE9: 0 | AF9: 0 | AG9: 0 | AH9: 0 | AI9: 0 | AJ9: 0 | AK9: 0 | AL9: 0 | AM9: 0 | AN9: 0 | AO9: 0 | AP9: 0 | AQ9: 0 | AR9: 0 | AS9: 0 | AT9: 0 | AU9: 0 | AV9: 0 | AW9: 0 | AX9: 0 | AY9: 0 | AZ9: 0 | BA9: 0 | BB9: 0 | BC9: 0 | BD9: 0 | BE9: 0 | BF9: 0 | BG9: 0 | BH9: 0 | BI9: 0 | BJ9: 0 | BK9: 0 | BL9: 0 | BM9: 0 | BN9: 0 | BO9: 0 | BP9: 0 | BQ9: 0 | BR9: 0 | BS9: 0 | BT9: 0 | BU9: 0 | BV9: 0 | BW9: 0 | BX9: 0 | BY9: 0 | BZ9: 0 | CA9: 0 | CB9: 0 | CC9: 0 | CD9: 0 | CE9: 0
A10: 0 | B10: 0 | C10: 0 | D10: 0 | E10: 0 | F10: 0 | G10: 0 | H10: 0 | I10: 0 | J10: 0 | K10: 0 | L10: 0 | M10: 0 | N10: 0 | O10: 0 | P10: 0 | Q10: 0 | R10: 0 | S10: 0 | T10: 0 | U10: 0 | V10: 0 | W10: 0 | X10: 0 | Y10: 0 | Z10: 0 | AA10: 0 | AB10: 0 | AC10: 0 | AD10: 0 | AE10: 0 | AF10: 0 | AG10: 0 | AH10: 0 | AI10: 0 | AJ10: 0 | AK10: 0 | AL10: 0 | AM10: 0 | AN10: 0 | AO10: 0 | AP10: 0 | AQ10: 0 | AR10: 0 | AS10: 0 | AT10: 0 | AU10: 0 | AV10: 0 | AW10: 0 | AX10: 0 | AY10: 0 | AZ10: 0 | BA10: 0 | BB10: 0 | BC10: 0 | BD10: 0 | BE10: 0 | BF10: 0 | BG10: 0 | BH10: 0 | BI10: 0 | BJ10: 0 | BK10: 0 | BL10: 0 | BM10: 0 | BN10: 0 | BO10: 0 | BP10: 0 | BQ10: 0 | BR10: 0 | BS10: 0 | BT10: 0 | BU10: 0 | BV10: 0 | BW10: 0 | BX10: 0 | BY10: 0 | BZ10: 0 | CA10: 0 | CB10: 0 | CC10: 0 | CD10: 0 | CE10: 0
A11: 0 | B11: 0 | C11: 0 | D11: 0 | E11: 0 | F11: 0 | G11: 0 | H11: 0 | I11: 0 | J11: 0 | K11: 0 | L11: 0 | M11: 0 | N11: 0 | O11: 0 | P11: 0 | Q11: 0 | R11: 0 | S11: 0 | T11: 0 | U11: 0 | V11: 0 | W11: 0 | X11: 0 | Y11: 0 | Z11: 0 | AA11: 0 | AB11: 0 | AC11: 0 | AD11: 0 | AE11: 0 | AF11: 0 | AG11: 0 | AH11: 0 | AI11: 0 | AJ11: 0 | AK11: 0 | AL11: 0 | AM11: 0 | AN11: 0 | AO11: 0 | AP11: 0 | AQ11: 0 | AR11: 0 | AS11: 0 | AT11: 0 | AU11: 0 | AV11: 0 | AW11: 0 | AX11: 0 | AY11: 0 | AZ11: 0 | BA11: 0 | BB11: 0 | BC11: 0 | BD11: 0 | BE11: 0 | BF11: 0 | BG11: 0 | BH11: 0 | BI11: 0 | BJ11: 0 | BK11: 0 | BL11: 0 | BM11: 0 | BN11: 0 | BO11: 0 | BP11: 0 | BQ11: 0 | BR11: 0 | BS11: 0 | BT11: 0 | BU11: 0 | BV11: 0 | BW11: 0 | BX11: 0 | BY11: 0 | BZ11: 0 | CA11: 0 | CB11: 0 | CC11: 0 | CD11: 0 | CE11: 0
A12: 0 | B12: 0 | C12: 0 | D12: 0 | E12: 0 | F12: 0 | G12: 0 | H12: 0 | I12: 0 | J12: 0 | K12: 0 | L12: 0 | M12: 0 | N12: 0 | O12: 0 | P12: 0 | Q12: 0 | R12: 0 | S12: 0 | T12: 0 | U12: 0 | V12: 0 | W12: 0 | X12: 0 | Y12: 0 | Z12: 0 | AA12: 0 | AB12: 0 | AC12: 0 | AD12: 0 | AE12: 0 | AF12: 0 | AG12: 0 | AH12: 0 | AI12: 0 | AJ12: 0 | AK12: 0 | AL12: 0 | AM12: 0 | AN12: 0 | AO12: 0 | AP12: 0 | AQ12: 0 | AR12: 0 | AS12: 0 | AT12: 0 | AU12: 0 | AV12: 0 | AW12: 0 | AX12: 0 | AY12: 0 | AZ12: 0 | BA12: 0 | BB12: 0 | BC12: 0 | BD12: 0 | BE12: 0 | BF12: 0 | BG12: 0 | BH12: 0 | BI12: 0 | BJ12: 0 | BK12: 0 | BL12: 0 | BM12: 0 | BN12: 0 | BO12: 0 | BP12: 0 | BQ12: 0 | BR12: 0 | BS12: 0 | BT12: 0 | BU12: 0 | BV12: 0 | BW12: 0 | BX12: 0 | BY12: 0 | BZ12: 0 | CA12: 0 | CB12: 0 | CC12: 0 | CD12: 0 | CE12: 0
A13: 0 | B13: 0 | C13: 0 | D13: 0 | E13: 0 | F13: 0 | G13: 0 | H13: 0 | I13: 0 | J13: 0 | K13: 0 | L13: 0 | M13: 0 | N13: 0 | O13: 0 | P13: 0 | Q13: 0 | R13: 0 | S13: 0 | T13: 0 | U13: 0 | V13: 0 | W13: 0 | X13: 0 | Y13: 0 | Z13: 0 | AA13: 0 | AB13: 0 | AC13: 0 | AD13: 0 | AE13: 0 | AF13: 0 | AG13: 0 | AH13: 0 | AI13: 0 | AJ13: 0 | AK13: 0 | AL13: 0 | AM13: 0 | AN13: 0 | AO13: 0 | AP13: 0 | AQ13: 0 | AR13: 0 | AS13: 0 | AT13: 0 | AU13: 0 | AV13: 0 | AW13: 0 | AX13: 0 | AY13: 0 | AZ13: 0 | BA13: 0 | BB13: 0 | BC13: 0 | BD13: 0 | BE13: 0 | BF13: 0 | BG13: 0 | BH13: 0 | BI13: 0 | BJ13: 0 | BK13: 0 | BL13: 0 | BM13: 0 | BN13: 0 | BO13: 0 | BP13: 0 | BQ13: 0 | BR13: 0 | BS13: 0 | BT13: 0 | BU13: 0 | BV13: 0 | BW13: 0 | BX13: 0 | BY13: 0 | BZ13: 0 | CA13: 0 | CB13: 0 | CC13: 0 | CD13: 0 | CE13: 0
A14: 0 | B14: 0 | C14: 0 | D14: 0 | E14: 0 | F14: 0 | G14: 0 | H14: 0 | I14: 0 | J14: 0 | K14: 0 | L14: 0 | M14: 0 | N14: 0 | O14: 0 | P14: 0 | Q14: 0 | R14: 0 | S14: 0 | T14: 0 | U14: 0 | V14: 0 | W14: 0 | X14: 0 | Y14: 0 | Z14: 0 | AA14: 0 | AB14: 0 | AC14: 0 | AD14: 0 | AE14: 0 | AF14: 0 | AG14: 0 | AH14: 0 | AI14: 0 | AJ14: 0 | AK14: 0 | AL14: 0 | AM14: 0 | AN14: 0 | AO14: 0 | AP14: 0 | AQ14: 0 | AR14: 0 | AS14: 0 | AT14: 0 | AU14: 0 | AV14: 0 | AW14: 0 | AX14: 0 | AY14: 0 | AZ14: 0 | BA14: 0 | BB14: 0 | BC14: 0 | BD14: 0 | BE14: 0 | BF14: 0 | BG14: 0 | BH14: 0 | BI14: 0 | BJ14: 0 | BK14: 0 | BL14: 0 | BM14: 0 | BN14: 0 | BO14: 0 | BP14: 0 | BQ14: 0 | BR14: 0 | BS14: 0 | BT14: 0 | BU14: 0 | BV14: 0 | BW14: 0 | BX14: 0 | BY14: 0 | BZ14: 0 | CA14: 0 | CB14: 0 | CC14: 0 | CD14: 0 | CE14: 0
A15: 0 | B15: 0 | C15: 0 | D15: 0 | E15: 0 | F15: 0 | G15: 0 | H15: 0 | I15: 0 | J15: 0 | K15: 0 | L15: 0 | M15: 0 | N15: 0 | O15: 0 | P15: 0 | Q15: 0 | R15: 0 | S15: 0 | T15: 0 | U15: 0 | V15: 0 | W15: 0 | X15: 0 | Y15: 0 | Z15: 0 | AA15: 0 | AB15: 0 | AC15: 0 | AD15: 0 | AE15: 0 | AF15: 0 | AG15: 0 | AH15: 0 | AI15: 0 | AJ15: 0 | AK15: 0 | AL15: 0 | AM15: 0 | AN15: 0 | AO15: 0 | AP15: 0 | AQ15: 0 | AR15: 0 | AS15: 0 | AT15: 0 | AU15: 0 | AV15: 0 | AW15: 0 | AX15: 0 | AY15: 0 | AZ15: 0 | BA15: 0 | BB15: 0 | BC15: 0 | BD15: 0 | BE15: 0 | BF15: 0 | BG15: 0 | BH15: 0 | BI15: 0 | BJ15: 0 | BK15: 0 | BL15: 0 | BM15: 0 | BN15: 0 | BO15: 0 | BP15: 0 | BQ15: 0 | BR15: 0 | BS15: 0 | BT15: 0 | BU15: 0 | BV15: 0 | BW15: 0 | BX15: 0 | BY15: 0 | BZ15: 0 | CA15: 0 | CB15: 0 | CC15: 0 | CD15: 0 | CE15: 0
A16: 0 | B16: 0 | C16: 0 | D16: 0 | E16: 0 | F16: 0 | G16: 0 | H16: 0 | I16: 0 | J16: 0 | K16: 0 | L16: 0 | M16: 0 | N16: 0 | O16: 0 | P16: 0 | Q16: 0 | R16: 0 | S16: 0 | T16: 0 | U16: 0 | V16: 0 | W16: 0 | X16: 0 | Y16: 0 | Z16: 0 | AA16: 0 | AB16: 0 | AC16: 0 | AD16: 0 | AE16: 0 | AF16: 0 | AG16: 0 | AH16: 0 | AI16: 0 | AJ16: 0 | AK16: 0 | AL16: 0 | AM16: 0 | AN16: 0 | AO16: 0 | AP16: 0 | AQ16: 0 | AR16: 0 | AS16: 0 | AT16: 0 | AU16: 0 | AV16: 0 | AW16: 0 | AX16: 0 | AY16: 0 | AZ16: 0 | BA16: 0 | BB16: 0 | BC16: 0 | BD16: 0 | BE16: 0 | BF16: 0 | BG16: 0 | BH16: 0 | BI16: 0 | BJ16: 0 | BK16: 0 | BL16: 0 | BM16: 0 | BN16: 0 | BO16: 0 | BP16: 0 | BQ16: 0 | BR16: 0 | BS16: 0 | BT16: 0 | BU16: 0 | BV16: 0 | BW16: 0 | BX16: 0 | BY16: 0 | BZ16: 0 | CA16: 0 | CB16: 0 | CC16: 0 | CD16: 0 | CE16: 0
... A99: 0 | B99: 0 | C99: 0 | D99: 0 | E99: 0 | F99: 0 | G99: 0 | H99: 0 | I99: 0 | J99: 0 | K99: 0 | L99: 0 | M99: 0 | N99: 0 | O99: 0 | P99: 0 | Q99: 0 | R99: 0 | S99: 0 | T99: 0 | U99: 0 | V99: 0 | W99: 0 | X99: 0 | Y99: 0 | Z99: 0 | AA99: 0 | AB99: 0 | AC99: 0 | AD99: 0 | AE99: 0 | AF99: 0 | AG99: 0 | AH99: 0 | AI99: 0 | AJ99: 0 | AK99: 0 | AL99: 0 | AM99: 0 | AN99: 0 | AO99: 0 | AP99: 0 | AQ99: 0 | AR99: 0 | AS99: 0 | AT99: 0 | AU99: 0 | AV99: 0 | AW99: 0 | AX99: 0 | AY99: 0 | AZ99: 0 | BA99: 0 | BB99: 0 | BC99: 0 | BD99: 0 | BE99: 0 | BF99: 0 | BG99: 0 | BH99: 0 | BI99: 0 | BJ99: 0 | BK99: 0 | BL99: 0 | BM99: 0 | BN99: 0 | BO99: 0 | BP99: 0 | BQ99: 0 | BR99: 0 | BS99: 0 | BT99: 0 | BU99: 0 | BV99: 0 | BW99: 0 | BX99: 0 | BY99: 0 | BZ99: 0 | CA99: 0 | CB99: 0 | CC99: 0 | CD99: 0 | CE99: 0
A100: =I_Wzorcowa_BD!A3 | E100: =VLOOKUP(A100,Listy!A:C,2,FALSE) & " : " & VLOOKUP(A100,Listy!A:C,3,FALSE) | BJ100: =O1 | BK100: Suma | BL100: Różnica | BM100: =SUM(BL101:BL199)
A101: =I_Wzorcowa_BD!A4 | B101: =I_Wzorcowa_BD!B4 | C101: =I_Wzorcowa_BD!C4 | D101: =I_Wzorcowa_BD!D4 | E101: =I_Wzorcowa_BD!E4 | F101: =I_Wzorcowa_BD!F4 | G101: =I_Wzorcowa_BD!G4 | H101: =I_Wzorcowa_BD!H4 | ... BI101: =I_Wzorcowa_BD!BI4 | BJ101: =O101 | BK101: =SUM(AG101:AW101) | BL101: =BJ101-BK101
A102: =I_Wzorcowa_BD!A5 | B102: =I_Wzorcowa_BD!B5 | C102: =I_Wzorcowa_BD!C5 | D102: =I_Wzorcowa_BD!D5 | E102: =I_Wzorcowa_BD!E5 | F102: =I_Wzorcowa_BD!F5 | G102: =I_Wzorcowa_BD!G5 | H102: =I_Wzorcowa_BD!H5 | ... BI102: =I_Wzorcowa_BD!BI5 | BJ102: =O102 | BK102: =SUM(AG102:AW102) | BL102: =BJ102-BK102
A103: =I_Wzorcowa_BD!A6 | B103: =I_Wzorcowa_BD!B6 | C103: =I_Wzorcowa_BD!C6 | D103: =I_Wzorcowa_BD!D6 | E103: =I_Wzorcowa_BD!E6 | F103: =I_Wzorcowa_BD!F6 | G103: =I_Wzorcowa_BD!G6 | H103: =I_Wzorcowa_BD!H6 | ... BI103: =I_Wzorcowa_BD!BI6 | BJ103: =O103 | BK103: =SUM(AG103:AW103) | BL103: =BJ103-BK103
A104: =I_Wzorcowa_BD!A7 | B104: =I_Wzorcowa_BD!B7 | C104: =I_Wzorcowa_BD!C7 | D104: =I_Wzorcowa_BD!D7 | E104: =I_Wzorcowa_BD!E7 | F104: =I_Wzorcowa_BD!F7 | G104: =I_Wzorcowa_BD!G7 | H104: =I_Wzorcowa_BD!H7 | ... BI104: =I_Wzorcowa_BD!BI7 | BJ104: =O104 | BK104: =SUM(AG104:AW104) | BL104: =BJ104-BK104
A105: =I_Wzorcowa_BD!A8 | B105: =I_Wzorcowa_BD!B8 | C105: =I_Wzorcowa_BD!C8 | D105: =I_Wzorcowa_BD!D8 | E105: =I_Wzorcowa_BD!E8 | F105: =I_Wzorcowa_BD!F8 | G105: =I_Wzorcowa_BD!G8 | H105: =I_Wzorcowa_BD!H8 | ... BI105: =I_Wzorcowa_BD!BI8 | BJ105: =O105 | BK105: =SUM(AG105:AW105) | BL105: =BJ105-BK105
A106: =I_Wzorcowa_BD!A9 | B106: =I_Wzorcowa_BD!B9 | C106: =I_Wzorcowa_BD!C9 | D106: =I_Wzorcowa_BD!D9 | E106: =I_Wzorcowa_BD!E9 | F106: =I_Wzorcowa_BD!F9 | G106: =I_Wzorcowa_BD!G9 | H106: =I_Wzorcowa_BD!H9 | ... BI106: =I_Wzorcowa_BD!BI9 | BJ106: =O106 | BK106: =SUM(AG106:AW106) | BL106: =BJ106-BK106
A107: =I_Wzorcowa_BD!A10 | B107: =I_Wzorcowa_BD!B10 | C107: =I_Wzorcowa_BD!C10 | D107: =I_Wzorcowa_BD!D10 | E107: =I_Wzorcowa_BD!E10 | F107: =I_Wzorcowa_BD!F10 | G107: =I_Wzorcowa_BD!G10 | H107: =I_Wzorcowa_BD!H10 | ... BI107: =I_Wzorcowa_BD!BI10 | BJ107: =O107 | BK107: =SUM(AG107:AW107) | BL107: =BJ107-BK107
A108: =I_Wzorcowa_BD!A11 | B108: =I_Wzorcowa_BD!B11 | C108: =I_Wzorcowa_BD!C11 | D108: =I_Wzorcowa_BD!D11 | E108: =I_Wzorcowa_BD!E11 | F108: =I_Wzorcowa_BD!F11 | G108: =I_Wzorcowa_BD!G11 | H108: =I_Wzorcowa_BD!H11 | ... BI108: =I_Wzorcowa_BD!BI11 | BJ108: =O108 | BK108: =SUM(AG108:AW108) | BL108: =BJ108-BK108
A109: =I_Wzorcowa_BD!A12 | B109: =I_Wzorcowa_BD!B12 | C109: =I_Wzorcowa_BD!C12 | D109: =I_Wzorcowa_BD!D12 | E109: =I_Wzorcowa_BD!E12 | F109: =I_Wzorcowa_BD!F12 | G109: =I_Wzorcowa_BD!G12 | H109: =I_Wzorcowa_BD!H12 | ... BI109: =I_Wzorcowa_BD!BI12 | BJ109: =O109 | BK109: =SUM(AG109:AW109) | BL109: =BJ109-BK109
A110: =I_Wzorcowa_BD!A13 | B110: =I_Wzorcowa_BD!B13 | C110: =I_Wzorcowa_BD!C13 | D110: =I_Wzorcowa_BD!D13 | E110: =I_Wzorcowa_BD!E13 | F110: =I_Wzorcowa_BD!F13 | G110: =I_Wzorcowa_BD!G13 | H110: =I_Wzorcowa_BD!H13 | ... BI110: =I_Wzorcowa_BD!BI13 | BJ110: =O110 | BK110: =SUM(AG110:AW110) | BL110: =BJ110-BK110
A111: =I_Wzorcowa_BD!A14 | B111: =I_Wzorcowa_BD!B14 | C111: =I_Wzorcowa_BD!C14 | D111: =I_Wzorcowa_BD!D14 | E111: =I_Wzorcowa_BD!E14 | F111: =I_Wzorcowa_BD!F14 | G111: =I_Wzorcowa_BD!G14 | H111: =I_Wzorcowa_BD!H14 | ... BI111: =I_Wzorcowa_BD!BI14 | BJ111: =O111 | BK111: =SUM(AG111:AW111) | BL111: =BJ111-BK111
A112: =I_Wzorcowa_BD!A15 | B112: =I_Wzorcowa_BD!B15 | C112: =I_Wzorcowa_BD!C15 | D112: =I_Wzorcowa_BD!D15 | E112: =I_Wzorcowa_BD!E15 | F112: =I_Wzorcowa_BD!F15 | G112: =I_Wzorcowa_BD!G15 | H112: =I_Wzorcowa_BD!H15 | ... BI112: =I_Wzorcowa_BD!BI15 | BJ112: =O112 | BK112: =SUM(AG112:AW112) | BL112: =BJ112-BK112
... A126: =I_Wzorcowa_BD!A29 | B126: =I_Wzorcowa_BD!B29 | C126: =I_Wzorcowa_BD!C29 | D126: =I_Wzorcowa_BD!D29 | E126: =I_Wzorcowa_BD!E29 | F126: =I_Wzorcowa_BD!F29 | G126: =I_Wzorcowa_BD!G29 | H126: =I_Wzorcowa_BD!H29 | ... BI126: =I_Wzorcowa_BD!BI29 | BJ126: =O126 | BK126: =SUM(AG126:AW126) | BL126: =BJ126-BK126
A127: =A100 | BJ127: =O127 | BK127: =SUM(AG127:AW127) | BL127: =BJ127-BK127
A128: =A127 | BJ128: =O128 | BK128: =SUM(AG128:AW128) | BL128: =BJ128-BK128
A129: =A128 | BJ129: =O129 | BK129: =SUM(AG129:AW129) | BL129: =BJ129-BK129
A130: =A129 | BJ130: =O130 | BK130: =SUM(AG130:AW130) | BL130: =BJ130-BK130
A131: =A130 | BJ131: =O131 | BK131: =SUM(AG131:AW131) | BL131: =BJ131-BK131
A132: =A131 | BJ132: =O132 | BK132: =SUM(AG132:AW132) | BL132: =BJ132-BK132
A133: =A132 | BJ133: =O133 | BK133: =SUM(AG133:AW133) | BL133: =BJ133-BK133
A134: =A133 | BJ134: =O134 | BK134: =SUM(AG134:AW134) | BL134: =BJ134-BK134
A135: =A134 | BJ135: =O135 | BK135: =SUM(AG135:AW135) | BL135: =BJ135-BK135
...

Sheet Kopia
A1: Nr zadania | B1: NrX | C1: Nr XX | D1: Kod działania | E1: Nazwa zadania / działania | F1: Imię | G1: Nazwisko | H1: Priorytet | I1: wykonawca | J1: Początek realizacji Tydzień | K1: Początek realizacji MM | L1: Koniec realizacji MM | M1: Koniec realizacji Tydzień | N1: Liczba tygodni | O1: Liczba godzin | P1: Janusz Strzelecki | Q1: Mariusz Cegliński | R1: Wojciech Mazur | S1: Tomasz Grzegorek | T1: Sebastian Kaczmar | U1: Dorota Duży | V1: Dariusz Gąsior | W1: Prog_8 | X1: Prog_9 | Y1: END Analityk Danych/ Inżynier ML 1 | Z1: END Analityk Danych/ Inżynier ML 2 | AA1: END Analityk Danych/ Inżynier ML 3 | AB1: END Inż. Automatyzacji | AC1: AGH - Profesor (max 50% etatu) | AD1: AGH - Pracownik naukowy 1 (max 50% etatu) | AE1: AGH Pracownik nukowy 2 (max 50% etatu) | AF1: AGH Pracownik naukowy 3 (max 50% etatu) | AG1: Janusz Strzelecki | AH1: Mariusz Cegliński | AI1: Wojciech Mazur | AJ1: Tomasz Grzegorek | AK1: Sebastian Kaczmar | AL1: Dorota Duży | AM1: Dariusz Gąsior | AN1: Prog_8 | AO1: Prog_9 | AP1: END Analityk Danych/ Inżynier ML 1 | AQ1: END Analityk Danych/ Inżynier ML 2 | AR1: END Analityk Danych/ Inżynier ML 3 | AS1: END Inż. Automatyzacji | AT1: AGH - Profesor (max 50% etatu) | AU1: AGH - Pracownik naukowy 1 (max 50% etatu) | AV1: AGH Pracownik nukowy 2 (max 50% etatu) | AW1: AGH Pracownik naukowy 3 (max 50% etatu) | AX1: Razem [h] | AY1: Część Etat [h} | AZ1: PLN/Etat | BA1: Razem | BB1: Razem | BC1: ENDAWA | BD1: Imię | BE1: Nazwisko | BF1: Termi realizacji | BG1: Liczba godzin | BH1: PLN/h | BI1: Razem | BJ1: Nazwa sprzętu | BK1: Okres używania | BL1: Amortyzacja [PLN] | BM1: Nazwa budynku | BN1: Uzywana powierzchnia [m2] | BO1: Amortyzacja [PLN] | BP1: Nazwa nieruchomości | BQ1: Okres używania | BR1: Czynsz dzierżawny [PLN] | BS1: Wieczyste uzytkowanie [PLN] | BT1: Nazwa/rodzaj | BU1: Liczba [szt.] | BV1: Wartość jednostkowa [PLN] | BW1: Razem [PLN] | BX1: Nazwa/rodzaj | BY1: Liczba [szt.] | BZ1: Wartość jednostkowa [PLN] | CA1: Razem [PLN] | CB1: Nazwa/rodzaj | CC1: Liczba [szt.] | CD1: Wartość jednostkowa [PLN] | CE1: Razem [PLN]
A2: 0 | B2: 0 | C2: 0 | D2: 0 | E2: 0 | F2: 0 | G2: 0 | H2: 0 | I2: 0 | J2: 0 | K2: 0 | L2: 0 | M2: 0 | N2: 0 | O2: 43909 | P2: 0 | Q2: 0 | R2: 0 | S2: 0 | T2: 0 | U2: 0 | V2: 0 | W2: 0 | X2: 0 | Y2: 0 | Z2: 0 | AA2: 0 | AB2: 0 | AC2: 0 | AD2: 0 | AE2: 0 | AF2: 0 | AG2: 4777 | AH2: 4768 | AI2: 4645 | AJ2: 4619 | AK2: 3071 | AL2: 2796 | AM2: 1955 | AN2: 1516 | AO2: 1554 | AP2: 3882 | AQ2: 3580 | AR2: 3576 | AS2: 2030 | AT2: 306 | AU2: 338 | AV2: 328 | AW2: 332 | AX2: 0 | AY2: 0 | AZ2: 0 | BA2: 0 | BB2: 0 | BC2: 0 | BD2: 0 | BE2: 0 | BF2: 0 | BG2: 0 | BH2: 0 | BI2: 0 | BJ2: 0 | BK2: 0 | BL2: 0 | BM2: 0 | BN2: 0 | BO2: 0 | BP2: 0 | BQ2: 0 | BR2: 0 | BS2: 0 | BT2: 0 | BU2: 0 | BV2: 0 | BW2: 0 | BX2: 0 | BY2: 0 | BZ2: 0 | CA2: 0 | CB2: 0 | CC2: 0 | CD2: 0 | CE2: 0
A3: 0 | B3: 0 | C3: 0 | D3: 0 | E3: 0 | F3: 0 | G3: 0 | H3: 0 | I3: 0 | J3: 0 | K3: 0 | L3: 0 | M3: 0 | N3: 0 | O3: 44073 | P3: 0 | Q3: 0 | R3: 0 | S3: 0 | T3: 0 | U3: 0 | V3: 0 | W3: 0 | X3: 0 | Y3: 0 | Z3: 0 | AA3: 0 | AB3: 0 | AC3: 0 | AD3: 0 | AE3: 0 | AF3: 0 | AG3: 0 | AH3: 0 | AI3: 0 | AJ3: 0 | AK3: 0 | AL3: 0 | AM3: 0 | AN3: 0 | AO3: 0 | AP3: 0 | AQ3: 0 | AR3: 0 | AS3: 0 | AT3: 0 | AU3: 0 | AV3: 0 | AW3: 0 | AX3: 0 | AY3: 0 | AZ3: 0 | BA3: 0 | BB3: 0 | BC3: 0 | BD3: 0 | BE3: 0 | BF3: 0 | BG3: 0 | BH3: 0 | BI3: 0 | BJ3: 0 | BK3: 0 | BL3: 0 | BM3: 0 | BN3: 0 | BO3: 0 | BP3: 0 | BQ3: 0 | BR3: 0 | BS3: 0 | BT3: 0 | BU3: 0 | BV3: 0 | BW3: 0 | BX3: 0 | BY3: 0 | BZ3: 0 | CA3: 0 | CB3: 0 | CC3: 0 | CD3: 0 | CE3: 0
A4: 0 | B4: 0 | C4: 0 | D4: 0 | E4: 0 | F4: 0 | G4: 0 | H4: 0 | I4: 0 | J4: 0 | K4: 0 | L4: 0 | M4: 0 | N4: 0 | O4: -164 | P4: 0 | Q4: 0 | R4: 0 | S4: 0 | T4: 0 | U4: 0 | V4: 0 | W4: 0 | X4: 0 | Y4: 0 | Z4: 0 | AA4: 0 | AB4: 0 | AC4: 0 | AD4: 0 | AE4: 0 | AF4: 0 | AG4: 0 | AH4: 0 | AI4: 0 | AJ4: 0 | AK4: 0 | AL4: 0 | AM4: 0 | AN4: 0 | AO4: 0 | AP4: 0 | AQ4: 0 | AR4: 0 | AS4: 0 | AT4: 0 | AU4: 0 | AV4: 0 | AW4: 0 | AX4: 0 | AY4: 0 | AZ4: 0 | BA4: 0 | BB4: 0 | BC4: 0 | BD4: 0 | BE4: 0 | BF4: 0 | BG4: 0 | BH4: 0 | BI4: 0 | BJ4: 0 | BK4: 0 | BL4: 0 | BM4: 0 | BN4: 0 | BO4: 0 | BP4: 0 | BQ4: 0 | BR4: 0 | BS4: 0 | BT4: 0 | BU4: 0 | BV4: 0 | BW4: 0 | BX4: 0 | BY4: 0 | BZ4: 0 | CA4: 0 | CB4: 0 | CC4: 0 | CD4: 0 | CE4: 0
A5: 0 | B5: 0 | C5: 0 | D5: 0 | E5: 0 | F5: 0 | G5: 0 | H5: 0 | I5: 0 | J5: 0 | K5: 0 | L5: 0 | M5: 0 | N5: 0 | O5: 0 | P5: 0 | Q5: 0 | R5: 0 | S5: 0 | T5: 0 | U5: 0 | V5: 0 | W5: 0 | X5: 0 | Y5: 0 | Z5: 0 | AA5: 0 | AB5: 0 | AC5: 0 | AD5: 0 | AE5: 0 | AF5: 0 | AG5: 0 | AH5: 0 | AI5: 0 | AJ5: 0 | AK5: 0 | AL5: 0 | AM5: 0 | AN5: 0 | AO5: 0 | AP5: 0 | AQ5: 0 | AR5: 0 | AS5: 0 | AT5: 0 | AU5: 0 | AV5: 0 | AW5: 0 | AX5: 0 | AY5: 0 | AZ5: 0 | BA5: 0 | BB5: 0 | BC5: 0 | BD5: 0 | BE5: 0 | BF5: 0 | BG5: 0 | BH5: 0 | BI5: 0 | BJ5: 0 | BK5: 0 | BL5: 0 | BM5: 0 | BN5: 0 | BO5: 0 | BP5: 0 | BQ5: 0 | BR5: 0 | BS5: 0 | BT5: 0 | BU5: 0 | BV5: 0 | BW5: 0 | BX5: 0 | BY5: 0 | BZ5: 0 | CA5: 0 | CB5: 0 | CC5: 0 | CD5: 0 | CE5: 0
A6: 0 | B6: 0 | C6: 0 | D6: 0 | E6: 0 | F6: 0 | G6: 0 | H6: 0 | I6: 0 | J6: 0 | K6: 0 | L6: 0 | M6: 0 | N6: 0 | O6: 0 | P6: 0 | Q6: 0 | R6: 0 | S6: 0 | T6: 0 | U6: 0 | V6: 0 | W6: 0 | X6: 0 | Y6: 0 | Z6: 0 | AA6: 0 | AB6: 0 | AC6: 0 | AD6: 0 | AE6: 0 | AF6: 0 | AG6: 0 | AH6: 0 | AI6: 0 | AJ6: 0 | AK6: 0 | AL6: 0 | AM6: 0 | AN6: 0 | AO6: 0 | AP6: 0 | AQ6: 0 | AR6: 0 | AS6: 0 | AT6: 0 | AU6: 0 | AV6: 0 | AW6: 0 | AX6: 0 | AY6: 0 | AZ6: 0 | BA6: 0 | BB6: 0 | BC6: 0 | BD6: 0 | BE6: 0 | BF6: 0 | BG6: 0 | BH6: 0 | BI6: 0 | BJ6: 0 | BK6: 0 | BL6: 0 | BM6: 0 | BN6: 0 | BO6: 0 | BP6: 0 | BQ6: 0 | BR6: 0 | BS6: 0 | BT6: 0 | BU6: 0 | BV6: 0 | BW6: 0 | BX6: 0 | BY6: 0 | BZ6: 0 | CA6: 0 | CB6: 0 | CC6: 0 | CD6: 0 | CE6: 0
A7: 0 | B7: 0 | C7: 0 | D7: 0 | E7: 0 | F7: 0 | G7: 0 | H7: 0 | I7: 0 | J7: 0 | K7: 0 | L7: 0 | M7: 0 | N7: 0 | O7: 0 | P7: 0 | Q7: 0 | R7: 0 | S7: 0 | T7: 0 | U7: 0 | V7: 0 | W7: 0 | X7: 0 | Y7: 0 | Z7: 0 | AA7: 0 | AB7: 0 | AC7: 0 | AD7: 0 | AE7: 0 | AF7: 0 | AG7: 0 | AH7: 0 | AI7: 0 | AJ7: 0 | AK7: 0 | AL7: 0 | AM7: 0 | AN7: 0 | AO7: 0 | AP7: 0 | AQ7: 0 | AR7: 0 | AS7: 0 | AT7: 0 | AU7: 0 | AV7: 0 | AW7: 0 | AX7: 0 | AY7: 0 | AZ7: 0 | BA7: 0 | BB7: 0 | BC7: 0 | BD7: 0 | BE7: 0 | BF7: 0 | BG7: 0 | BH7: 0 | BI7: 0 | BJ7: 0 | BK7: 0 | BL7: 0 | BM7: 0 | BN7: 0 | BO7: 0 | BP7: 0 | BQ7: 0 | BR7: 0 | BS7: 0 | BT7: 0 | BU7: 0 | BV7: 0 | BW7: 0 | BX7: 0 | BY7: 0 | BZ7: 0 | CA7: 0 | CB7: 0 | CC7: 0 | CD7: 0 | CE7: 0
A8: 0 | B8: 0 | C8: 0 | D8: 0 | E8: 0 | F8: 0 | G8: 0 | H8: 0 | I8: 0 | J8: 0 | K8: 0 | L8: 0 | M8: 0 | N8: 0 | O8: 0 | P8: 0 | Q8: 0 | R8: 0 | S8: 0 | T8: 0 | U8: 0 | V8: 0 | W8: 0 | X8: 0 | Y8: 0 | Z8: 0 | AA8: 0 | AB8: 0 | AC8: 0 | AD8: 0 | AE8: 0 | AF8: 0 | AG8: 0 | AH8: 0 | AI8: 0 | AJ8: 0 | AK8: 0 | AL8: 0 | AM8: 0 | AN8: 0 | AO8: 0 | AP8: 0 | AQ8: 0 | AR8: 0 | AS8: 0 | AT8: 0 | AU8: 0 | AV8: 0 | AW8: 0 | AX8: 0 | AY8: 0 | AZ8: 0 | BA8: 0 | BB8: 0 | BC8: 0 | BD8: 0 | BE8: 0 | BF8: 0 | BG8: 0 | BH8: 0 | BI8: 0 | BJ8: 0 | BK8: 0 | BL8: 0 | BM8: 0 | BN8: 0 | BO8: 0 | BP8: 0 | BQ8: 0 | BR8: 0 | BS8: 0 | BT8: 0 | BU8: 0 | BV8: 0 | BW8: 0 | BX8: 0 | BY8: 0 | BZ8: 0 | CA8: 0 | CB8: 0 | CC8: 0 | CD8: 0 | CE8: 0
A9: 0 | B9: 0 | C9: 0 | D9: 0 | E9: 0 | F9: 0 | G9: 0 | H9: 0 | I9: 0 | J9: 0 | K9: 0 | L9: 0 | M9: 0 | N9: 0 | O9: 0 | P9: 0 | Q9: 0 | R9: 0 | S9: 0 | T9: 0 | U9: 0 | V9: 0 | W9: 0 | X9: 0 | Y9: 0 | Z9: 0 | AA9: 0 | AB9: 0 | AC9: 0 | AD9: 0 | AE9: 0 | AF9: 0 | AG9: 0 | AH9: 0 | AI9: 0 | AJ9: 0 | AK9: 0 | AL9: 0 | AM9: 0 | AN9: 0 | AO9: 0 | AP9: 0 | AQ9: 0 | AR9: 0 | AS9: 0 | AT9: 0 | AU9: 0 | AV9: 0 | AW9: 0 | AX9: 0 | AY9: 0 | AZ9: 0 | BA9: 0 | BB9: 0 | BC9: 0 | BD9: 0 | BE9: 0 | BF9: 0 | BG9: 0 | BH9: 0 | BI9: 0 | BJ9: 0 | BK9: 0 | BL9: 0 | BM9: 0 | BN9: 0 | BO9: 0 | BP9: 0 | BQ9: 0 | BR9: 0 | BS9: 0 | BT9: 0 | BU9: 0 | BV9: 0 | BW9: 0 | BX9: 0 | BY9: 0 | BZ9: 0 | CA9: 0 | CB9: 0 | CC9: 0 | CD9: 0 | CE9: 0
A10: 0 | B10: 0 | C10: 0 | D10: 0 | E10: 0 | F10: 0 | G10: 0 | H10: 0 | I10: 0 | J10: 0 | K10: 0 | L10: 0 | M10: 0 | N10: 0 | O10: 0 | P10: 0 | Q10: 0 | R10: 0 | S10: 0 | T10: 0 | U10: 0 | V10: 0 | W10: 0 | X10: 0 | Y10: 0 | Z10: 0 | AA10: 0 | AB10: 0 | AC10: 0 | AD10: 0 | AE10: 0 | AF10: 0 | AG10: 0 | AH10: 0 | AI10: 0 | AJ10: 0 | AK10: 0 | AL10: 0 | AM10: 0 | AN10: 0 | AO10: 0 | AP10: 0 | AQ10: 0 | AR10: 0 | AS10: 0 | AT10: 0 | AU10: 0 | AV10: 0 | AW10: 0 | AX10: 0 | AY10: 0 | AZ10: 0 | BA10: 0 | BB10: 0 | BC10: 0 | BD10: 0 | BE10: 0 | BF10: 0 | BG10: 0 | BH10: 0 | BI10: 0 | BJ10: 0 | BK10: 0 | BL10: 0 | BM10: 0 | BN10: 0 | BO10: 0 | BP10: 0 | BQ10: 0 | BR10: 0 | BS10: 0 | BT10: 0 | BU10: 0 | BV10: 0 | BW10: 0 | BX10: 0 | BY10: 0 | BZ10: 0 | CA10: 0 | CB10: 0 | CC10: 0 | CD10: 0 | CE10: 0
A11: 0 | B11: 0 | C11: 0 | D11: 0 | E11: 0 | F11: 0 | G11: 0 | H11: 0 | I11: 0 | J11: 0 | K11: 0 | L11: 0 | M11: 0 | N11: 0 | O11: 0 | P11: 0 | Q11: 0 | R11: 0 | S11: 0 | T11: 0 | U11: 0 | V11: 0 | W11: 0 | X11: 0 | Y11: 0 | Z11: 0 | AA11: 0 | AB11: 0 | AC11: 0 | AD11: 0 | AE11: 0 | AF11: 0 | AG11: 0 | AH11: 0 | AI11: 0 | AJ11: 0 | AK11: 0 | AL11: 0 | AM11: 0 | AN11: 0 | AO11: 0 | AP11: 0 | AQ11: 0 | AR11: 0 | AS11: 0 | AT11: 0 | AU11: 0 | AV11: 0 | AW11: 0 | AX11: 0 | AY11: 0 | AZ11: 0 | BA11: 0 | BB11: 0 | BC11: 0 | BD11: 0 | BE11: 0 | BF11: 0 | BG11: 0 | BH11: 0 | BI11: 0 | BJ11: 0 | BK11: 0 | BL11: 0 | BM11: 0 | BN11: 0 | BO11: 0 | BP11: 0 | BQ11: 0 | BR11: 0 | BS11: 0 | BT11: 0 | BU11: 0 | BV11: 0 | BW11: 0 | BX11: 0 | BY11: 0 | BZ11: 0 | CA11: 0 | CB11: 0 | CC11: 0 | CD11: 0 | CE11: 0
A12: 0 | B12: 0 | C12: 0 | D12: 0 | E12: 0 | F12: 0 | G12: 0 | H12: 0 | I12: 0 | J12: 0 | K12: 0 | L12: 0 | M12: 0 | N12: 0 | O12: 0 | P12: 0 | Q12: 0 | R12: 0 | S12: 0 | T12: 0 | U12: 0 | V12: 0 | W12: 0 | X12: 0 | Y12: 0 | Z12: 0 | AA12: 0 | AB12: 0 | AC12: 0 | AD12: 0 | AE12: 0 | AF12: 0 | AG12: 0 | AH12: 0 | AI12: 0 | AJ12: 0 | AK12: 0 | AL12: 0 | AM12: 0 | AN12: 0 | AO12: 0 | AP12: 0 | AQ12: 0 | AR12: 0 | AS12: 0 | AT12: 0 | AU12: 0 | AV12: 0 | AW12: 0 | AX12: 0 | AY12: 0 | AZ12: 0 | BA12: 0 | BB12: 0 | BC12: 0 | BD12: 0 | BE12: 0 | BF12: 0 | BG12: 0 | BH12: 0 | BI12: 0 | BJ12: 0 | BK12: 0 | BL12: 0 | BM12: 0 | BN12: 0 | BO12: 0 | BP12: 0 | BQ12: 0 | BR12: 0 | BS12: 0 | BT12: 0 | BU12: 0 | BV12: 0 | BW12: 0 | BX12: 0 | BY12: 0 | BZ12: 0 | CA12: 0 | CB12: 0 | CC12: 0 | CD12: 0 | CE12: 0
A13: 0 | B13: 0 | C13: 0 | D13: 0 | E13: 0 | F13: 0 | G13: 0 | H13: 0 | I13: 0 | J13: 0 | K13: 0 | L13: 0 | M13: 0 | N13: 0 | O13: 0 | P13: 0 | Q13: 0 | R13: 0 | S13: 0 | T13: 0 | U13: 0 | V13: 0 | W13: 0 | X13: 0 | Y13: 0 | Z13: 0 | AA13: 0 | AB13: 0 | AC13: 0 | AD13: 0 | AE13: 0 | AF13: 0 | AG13: 0 | AH13: 0 | AI13: 0 | AJ13: 0 | AK13: 0 | AL13: 0 | AM13: 0 | AN13: 0 | AO13: 0 | AP13: 0 | AQ13: 0 | AR13: 0 | AS13: 0 | AT13: 0 | AU13: 0 | AV13: 0 | AW13: 0 | AX13: 0 | AY13: 0 | AZ13: 0 | BA13: 0 | BB13: 0 | BC13: 0 | BD13: 0 | BE13: 0 | BF13: 0 | BG13: 0 | BH13: 0 | BI13: 0 | BJ13: 0 | BK13: 0 | BL13: 0 | BM13: 0 | BN13: 0 | BO13: 0 | BP13: 0 | BQ13: 0 | BR13: 0 | BS13: 0 | BT13: 0 | BU13: 0 | BV13: 0 | BW13: 0 | BX13: 0 | BY13: 0 | BZ13: 0 | CA13: 0 | CB13: 0 | CC13: 0 | CD13: 0 | CE13: 0
... A99: 0 | B99: 0 | C99: 0 | D99: 0 | E99: 0 | F99: 0 | G99: 0 | H99: 0 | I99: 0 | J99: 0 | K99: 0 | L99: 0 | M99: 0 | N99: 0 | O99: 0 | P99: 0 | Q99: 0 | R99: 0 | S99: 0 | T99: 0 | U99: 0 | V99: 0 | W99: 0 | X99: 0 | Y99: 0 | Z99: 0 | AA99: 0 | AB99: 0 | AC99: 0 | AD99: 0 | AE99: 0 | AF99: 0 | AG99: 0 | AH99: 0 | AI99: 0 | AJ99: 0 | AK99: 0 | AL99: 0 | AM99: 0 | AN99: 0 | AO99: 0 | AP99: 0 | AQ99: 0 | AR99: 0 | AS99: 0 | AT99: 0 | AU99: 0 | AV99: 0 | AW99: 0 | AX99: 0 | AY99: 0 | AZ99: 0 | BA99: 0 | BB99: 0 | BC99: 0 | BD99: 0 | BE99: 0 | BF99: 0 | BG99: 0 | BH99: 0 | BI99: 0 | BJ99: 0 | BK99: 0 | BL99: 0 | BM99: 0 | BN99: 0 | BO99: 0 | BP99: 0 | BQ99: 0 | BR99: 0 | BS99: 0 | BT99: 0 | BU99: 0 | BV99: 0 | BW99: 0 | BX99: 0 | BY99: 0 | BZ99: 0 | CA99: 0 | CB99: 0 | CC99: 0 | CD99: 0 | CE99: 0
A100: .z01 | E100: Zadanie_I : Opracowanie autorskiej, kompleksowej, jednorodnej, standaryzowanej, skalowalnej wzorcowej bazy danych (WBD) procesów magazynowych, gotowej do analiz i procesowania w kolejnych elementach technologii inteligentnej platformy ICT, na potrzeby optymalizacji procesu przygotowywania i realizacji zamówień z wykorzystaniem mechanizmów AI i ML | BJ100: Liczba godzin | BK100: Suma | BL100: Różnica | BM100: 21
A101: 1 | B101: a | C101: -1 | D101: .z01_1_a_-1 | E101: 1.Opracowanie koncepcji standaryzowanej wzorcowej bazy danych | F101: 0 | G101: ACT | H101: 0 | I101: ACT | J101: 0 | K101: 0 | L101: 0 | M101: 0 | N101: 0 | O101: 0 | P101: 0 | Q101: 0 | R101: 0 | S101: 0 | T101: 0 | U101: 0 | V101: 0 | W101: 0 | X101: 0 | Y101: 0 | Z101: 0 | AA101: 0 | AB101: 0 | AC101: 0 | AD101: 0 | AE101: 0 | AF101: 0 | AG101: 0 | AH101: 0 | AI101: 0 | AJ101: 0 | AK101: 0 | AL101: 0 | AM101: 0 | AN101: 0 | AO101: 0 | AP101: 0 | AQ101: 0 | AR101: 0 | AS101: 0 | AT101: 0 | AU101: 0 | AV101: 0 | AW101: 0 | AX101: 0 | AY101: 0 | AZ101: 0 | BA101: 0 | BB101: 0 | BC101: 0 | BD101: 0 | BE101: 0 | BF101: 0 | BG101: 0 | BH101: 0 | BI101: 0 | BJ101: 0 | BK101: 0 | BL101: 0
A102: 1 | B102: a | C102: 0 | D102: .z01_1_a_0 | E102: 1.a.Projektowanie struktury bazy danych, która zapewni jej wydajność, spójność i skalowalność | F102: 0 | G102: 0 | H102: 0 | I102: 0 | J102: 1 | K102: 46204 | L102: 46204 | M102: 0 | N102: 0 | O102: 0 | P102: 0 | Q102: 0 | R102: 0 | S102: 0 | T102: 0 | U102: 0 | V102: 0 | W102: 0 | X102: 0 | Y102: 0 | Z102: 0 | AA102: 0 | AB102: 0 | AC102: 0 | AD102: 0 | AE102: 0 | AF102: 0 | AG102: 0 | AH102: 0 | AI102: 0 | AJ102: 0 | AK102: 0 | AL102: 0 | AM102: 0 | AN102: 0 | AO102: 0 | AP102: 0 | AQ102: 0 | AR102: 0 | AS102: 0 | AT102: 0 | AU102: 0 | AV102: 0 | AW102: 0 | AX102: 0 | AY102: 0 | AZ102: 0 | BA102: 0 | BB102: 0 | BC102: 0 | BD102: 0 | BE102: 0 | BF102: 0 | BG102: 0 | BH102: 0 | BI102: 0 | BJ102: 0 | BK102: 0 | BL102: 0
A103: 1 | B103: a | C103: 1 | D103: .z01_1_a_1 | E103: Opracowanie logicznego i fizycznego modelu bazy danych, uwzględniającego wszystkie kluczowe elementy (np. tabele, relacje, indeksy i klucze) | F103: Imię02 | G103: ACT | H103: 1 | I103: .a02 | J103: 1 | K103: 46204 | L103: 46208 | M103: 4 | N103: 4 | O103: 320 | P103: 0.25 | Q103: 0.25 | R103: 0.25 | S103: 0.25 | T103: 0 | U103: 0 | V103: 0 | W103: 0 | X103: 0 | Y103: 0 | Z103: 0 | AA103: 0 | AB103: 0 | AC103: 0 | AD103: 0 | AE103: 0 | AF103: 0 | AG103: 80 | AH103: 80 | AI103: 80 | AJ103: 80 | AK103: 0 | AL103: 0 | AM103: 0 | AN103: 0 | AO103: 0 | AP103: 0 | AQ103: 0 | AR103: 0 | AS103: 0 | AT103: 0 | AU103: 0 | AV103: 0 | AW103: 0 | AX103: 320 | AY103: 2 | AZ103: 5002 | BA103: 10004 | BB103: 20008 | BC103: 0 | BD103: 0 | BE103: 0 | BF103: 0 | BG103: 0 | BH103: 0 | BI103: 0 | BJ103: 320 | BK103: 320 | BL103: 0
A104: 1 | B104: a | C104: 2 | D104: .z01_1_a_2 | E104: Opracowanie architektury systemu, zapewniającą obsługę rosnącej ilości danych celem szybkiego i efektywnego ich przetwarzania | F104: Imię03 | G104: ACT | H104: 1 | I104: .a03 | J104: 5 | K104: 46232 | L104: 46232 | M104: 4 | N104: 0 | O104: 40 | P104: 0.2 | Q104: 0.2 | R104: 0.2 | S104: 0.2 | T104: 0 | U104: 0 | V104: 0 | W104: 0 | X104: 0 | Y104: 0 | Z104: 0 | AA104: 0 | AB104: 0 | AC104: 0 | AD104: 0 | AE104: 0 | AF104: 0 | AG104: 8 | AH104: 8 | AI104: 8 | AJ104: 8 | AK104: 0 | AL104: 0 | AM104: 0 | AN104: 0 | AO104: 0 | AP104: 0 | AQ104: 0 | AR104: 0 | AS104: 0 | AT104: 0 | AU104: 0 | AV104: 0 | AW104: 0 | AX104: 32 | AY104: 0.2 | AZ104: 5003 | BA104: 1000.6 | BB104: 200.12 | BC104: 0 | BD104: 0 | BE104: 0 | BF104: 0 | BG104: 0 | BH104: 0 | BI104: 0 | BJ104: 40 | BK104: 32 | BL104: 8
A105: 1 | B105: a | C105: 3 | D105: .z01_1_a_3 | E105: Opracowanie mechanizmów do administrowania, eksploatacji i monitorowania bazy danych oraz współpracy z modułami planowanej platformy ICT | F105: Imię01 | G105: ACT | H105: 1 | I105: .a01 | J105: 5 | K105: 46232 | L105: 46232 | M105: 4 | N105: 0 | O105: 40 | P105: 0.2 | Q105: 0.2 | R105: 0.2 | S105: 0.2 | T105: 0 | U105: 0 | V105: 0 | W105: 0 | X105: 0 | Y105: 0 | Z105: 0 | AA105: 0 | AB105: 0 | AC105: 0 | AD105: 0 | AE105: 0 | AF105: 0 | AG105: 8 | AH105: 8 | AI105: 8 | AJ105: 8 | AK105: 0 | AL105: 0 | AM105: 0 | AN105: 0 | AO105: 0 | AP105: 0 | AQ105: 0 | AR105: 0 | AS105: 0 | AT105: 0 | AU105: 0 | AV105: 0 | AW105: 0 | AX105: 32 | AY105: 0.2 | AZ105: 5001 | BA105: 1000.2 | BB105: 200.04 | BC105: 0 | BD105: 0 | BE105: 0 | BF105: 0 | BG105: 0 | BH105: 0 | BI105: 0 | BJ105: 40 | BK105: 32 | BL105: 8
A106: 1 | B106: a | C106: 4 | D106: .z01_1_a_4 | E106: Testowanie, walidacja i optymalizacja projektu struktury bazy danych | F106: Imię03 | G106: ACT | H106: 1 | I106: .a03 | J106: 5 | K106: 46232 | L106: 46232 | M106: 4 | N106: 0 | O106: 40 | P106: 0.2 | Q106: 0.2 | R106: 0.2 | S106: 0.2 | T106: 0 | U106: 0 | V106: 0 | W106: 0 | X106: 0 | Y106: 0 | Z106: 0 | AA106: 0 | AB106: 0 | AC106: 0 | AD106: 0 | AE106: 0 | AF106: 0 | AG106: 8 | AH106: 8 | AI106: 8 | AJ106: 8 | AK106: 0 | AL106: 0 | AM106: 0 | AN106: 0 | AO106: 0 | AP106: 0 | AQ106: 0 | AR106: 0 | AS106: 0 | AT106: 0 | AU106: 0 | AV106: 0 | AW106: 0 | AX106: 32 | AY106: 0.2 | AZ106: 5003 | BA106: 1000.6 | BB106: 200.12 | BC106: 0 | BD106: 0 | BE106: 0 | BF106: 0 | BG106: 0 | BH106: 0 | BI106: 0 | BJ106: 40 | BK106: 32 | BL106: 8
A107: 1 | B107: b | C107: 0 | D107: .z01_1_b_0 | E107: 1.b.Zbieranie i przygotowanie danych w celu uzyskania pełnego obrazu operacji w magazynie i umożliwienia kompleksowych analiz | F107: 0 | G107: 0 | H107: 0 | I107: 0 | J107: 1 | K107: 46204 | L107: 46204 | M107: 0 | N107: 0 | O107: 0 | P107: 0 | Q107: 0 | R107: 0 | S107: 0 | T107: 0 | U107: 0 | V107: 0 | W107: 0 | X107: 0 | Y107: 0 | Z107: 0 | AA107: 0 | AB107: 0 | AC107: 0 | AD107: 0 | AE107: 0 | AF107: 0 | AG107: 0 | AH107: 0 | AI107: 0 | AJ107: 0 | AK107: 0 | AL107: 0 | AM107: 0 | AN107: 0 | AO107: 0 | AP107: 0 | AQ107: 0 | AR107: 0 | AS107: 0 | AT107: 0 | AU107: 0 | AV107: 0 | AW107: 0 | AX107: 0 | AY107: 0 | AZ107: 0 | BA107: 0 | BB107: 0 | BC107: 0 | BD107: 0 | BE107: 0 | BF107: 0 | BG107: 0 | BH107: 0 | BI107: 0 | BJ107: 0 | BK107: 0 | BL107: 0
A108: 1 | B108: b | C108: 1 | D108: .z01_1_b_1 | E108: Stworzenie procedur zbierania, analizy i przetwarzania danych | F108: Imię02 | G108: ACT | H108: 1 | I108: .a02 | J108: 1 | K108: 46204 | L108: 46205 | M108: 1 | N108: 1 | O108: 90 | P108: 0 | Q108: 0 | R108: 0 | S108: 0 | T108: 0.2 | U108: 0.2 | V108: 0.2 | W108: 0.2 | X108: 0.2 | Y108: 0 | Z108: 0 | AA108: 0 | AB108: 0 | AC108: 0 | AD108: 0 | AE108: 0 | AF108: 0 | AG108: 0 | AH108: 0 | AI108: 0 | AJ108: 0 | AK108: 18 | AL108: 18 | AM108: 18 | AN108: 18 | AO108: 18 | AP108: 0 | AQ108: 0 | AR108: 0 | AS108: 0 | AT108: 0 | AU108: 0 | AV108: 0 | AW108: 0 | AX108: 90 | AY108: 0.5625 | AZ108: 5002 | BA108: 2813.625 | BB108: 1582.6641 | BC108: 0 | BD108: 0 | BE108: 0 | BF108: 0 | BG108: 0 | BH108: 0 | BI108: 0 | BJ108: 90 | BK108: 90 | BL108: 0
A109: 1 | B109: b | C109: 2 | D109: .z01_1_b_2 | E109: Pozyskanie danych z różnych źródeł, np. systemy WMS, ERP | F109: Imię01 | G109: ACT | H109: 1 | I109: .a01 | J109: 2 | K109: 46211 | L109: 46213 | M109: 3 | N109: 2 | O109: 160 | P109: 0 | Q109: 0 | R109: 0 | S109: 0 | T109: 0.2 | U109: 0.2 | V109: 0.2 | W109: 0.2 | X109: 0.2 | Y109: 0 | Z109: 0 | AA109: 0 | AB109: 0 | AC109: 0 | AD109: 0 | AE109: 0 | AF109: 0 | AG109: 0 | AH109: 0 | AI109: 0 | AJ109: 0 | AK109: 32 | AL109: 32 | AM109: 32 | AN109: 32 | AO109: 32 | AP109: 0 | AQ109: 0 | AR109: 0 | AS109: 0 | AT109: 0 | AU109: 0 | AV109: 0 | AW109: 0 | AX109: 160 | AY109: 1 | AZ109: 5001 | BA109: 5001 | BB109: 5001 | BC109: 0 | BD109: 0 | BE109: 0 | BF109: 0 | BG109: 0 | BH109: 0 | BI109: 0 | BJ109: 160 | BK109: 160 | BL109: 0
A110: 1 | B110: b | C110: 3 | D110: .z01_1_b_3 | E110: Identyfikacja aktualnie przypisywanych atrybutów do rekordów/obiektów w WMS/ERP | F110: Imię02 | G110: ACT | H110: 1 | I110: .a02 | J110: 4 | K110: 46225 | L110: 46226 | M110: 4 | N110: 1 | O110: 120 | P110: 0 | Q110: 0 | R110: 0 | S110: 0 | T110: 0.2 | U110: 0.2 | V110: 0.2 | W110: 0.2 | X110: 0.2 | Y110: 0 | Z110: 0 | AA110: 0 | AB110: 0 | AC110: 0 | AD110: 0 | AE110: 0 | AF110: 0 | AG110: 0 | AH110: 0 | AI110: 0 | AJ110: 0 | AK110: 24 | AL110: 24 | AM110: 24 | AN110: 24 | AO110: 24 | AP110: 0 | AQ110: 0 | AR110: 0 | AS110: 0 | AT110: 0 | AU110: 0 | AV110: 0 | AW110: 0 | AX110: 120 | AY110: 0.75 | AZ110: 5002 | BA110: 3751.5 | BB110: 2813.625 | BC110: 0 | BD110: 0 | BE110: 0 | BF110: 0 | BG110: 0 | BH110: 0 | BI110: 0 | BJ110: 120 | BK110: 120 | BL110: 0
A111: 1 | B111: b | C111: 4 | D111: .z01_1_b_4 | E111: Opracowanie założeń modeli, schematów, organizacji i prezentacji danych wejściowych | F111: Imię03 | G111: ACT | H111: 1 | I111: .a03 | J111: 5 | K111: 46232 | L111: 46234 | M111: 6 | N111: 2 | O111: 180 | P111: 0 | Q111: 0 | R111: 0 | S111: 0 | T111: 0.2 | U111: 0.2 | V111: 0.2 | W111: 0.2 | X111: 0.2 | Y111: 0 | Z111: 0 | AA111: 0 | AB111: 0 | AC111: 0 | AD111: 0 | AE111: 0 | AF111: 0 | AG111: 0 | AH111: 0 | AI111: 0 | AJ111: 0 | AK111: 36 | AL111: 36 | AM111: 36 | AN111: 36 | AO111: 36 | AP111: 0 | AQ111: 0 | AR111: 0 | AS111: 0 | AT111: 0 | AU111: 0 | AV111: 0 | AW111: 0 | AX111: 180 | AY111: 1.125 | AZ111: 5003 | BA111: 5628.375 | BB111: 6331.9219 | BC111: 0 | BD111: 0 | BE111: 0 | BF111: 0 | BG111: 0 | BH111: 0 | BI111: 0 | BJ111: 180 | BK111: 180 | BL111: 0
A112: 1 | B112: c | C112: 1 | D112: .z01_1_c_1 | E112: Zgromadzenie danych historycznych (ostatnie 3 lata), dot. procesów omawianych w ramach niniejszego projektu | F112: 0 | G112: ACT | H112: 2 | I112: .a01 | J112: 7 | K112: 46246 | L112: 46247 | M112: 7 | N112: 1 | O112: 180 | P112: 0.11 | Q112: 0.11 | R112: 0.11 | S112: 0.11 | T112: 0.11 | U112: 0.11 | V112: 0.11 | W112: 0.11 | X112: 0.12 | Y112: 0 | Z112: 0 | AA112: 0 | AB112: 0 | AC112: 0 | AD112: 0 | AE112: 0 | AF112: 0 | AG112: 20 | AH112: 20 | AI112: 20 | AJ112: 20 | AK112: 20 | AL112: 20 | AM112: 20 | AN112: 20 | AO112: 20 | AP112: 0 | AQ112: 0 | AR112: 0 | AS112: 0 | AT112: 0 | AU112: 0 | AV112: 0 | AW112: 0 | AX112: 180 | AY112: 1.125 | AZ112: 5001 | BA112: 5626.125 | BB112: 6329.3906 | BC112: 0 | BD112: 0 | BE112: 0 | BF112: 0 | BG112: 0 | BH112: 0 | BI112: 0 | BJ112: 180 | BK112: 180 | BL112: 0
A113: 1 | B113: d | C113: 1 | D113: .z01_1_d_1 | E113: Oczyszczanie, normalizacja, konwersja i standaryzacja danych (procedury ETL), w tym usuwanie duplikatów i korekcji błędów, do jednolitego formatu na potrzeby dokładności analiz i predykcji, spójności i możliwość łatwego przetwarzania | F113: Imię03 | G113: ACT | H113: 3 | I113: .a03 | J113: 8 | K113: 46253 | L113: 46254 | M113: 8 | N113: 1 | O113: 180 | P113: 0.11 | Q113: 0.11 | R113: 0.11 | S113: 0.11 | T113: 0.11 | U113: 0.11 | V113: 0.11 | W113: 0.11 | X113: 0.12 | Y113: 0 | Z113: 0 | AA113: 0 | AB113: 0 | AC113: 0 | AD113: 0 | AE113: 0 | AF113: 0 | AG113: 20 | AH113: 20 | AI113: 20 | AJ113: 20 | AK113: 20 | AL113: 20 | AM113: 20 | AN113: 20 | AO113: 20 | AP113: 0 | AQ113: 0 | AR113: 0 | AS113: 0 | AT113: 0 | AU113: 0 | AV113: 0 | AW113: 0 | AX113: 180 | AY113: 1.125 | AZ113: 5003 | BA113: 5628.375 | BB113: 6331.9219 | BC113: 0 | BD113: 0 | BE113: 0 | BF113: 0 | BG113: 0 | BH113: 0 | BI113: 0 | BJ113: 180 | BK113: 180 | BL113: 0
A114: 2 | B114: a | C114: 0 | D114: .z01_2_a_0 | E114: 2.Implementacja WBD w infrastrukturze Wnioskodawcy w oparciu o wybrane platformy bazodanowe, np. Oracle, MSSQL, MySQL | F114: 0 | G114: 0 | H114: 0 | I114: 0 | J114: 9 | K114: 46260 | L114: 46260 | M114: 8 | N114: 0 | O114: 0 | P114: 0 | Q114: 0 | R114: 0 | S114: 0 | T114: 0 | U114: 0 | V114: 0 | W114: 0 | X114: 0 | Y114: 0 | Z114: 0 | AA114: 0 | AB114: 0 | AC114: 0 | AD114: 0 | AE114: 0 | AF114: 0 | AG114: 0 | AH114: 0 | AI114: 0 | AJ114: 0 | AK114: 0 | AL114: 0 | AM114: 0 | AN114: 0 | AO114: 0 | AP114: 0 | AQ114: 0 | AR114: 0 | AS114: 0 | AT114: 0 | AU114: 0 | AV114: 0 | AW114: 0 | AX114: 0 | AY114: 0 | AZ114: 0 | BA114: 0 | BB114: 0 | BC114: 0 | BD114: 0 | BE114: 0 | BF114: 0 | BG114: 0 | BH114: 0 | BI114: 0 | BJ114: 0 | BK114: 0 | BL114: 0
A115: 2 | B115: a | C115: 1 | D115: .z01_2_a_1 | E115: Testowanie i walidacja platform bazodanowych (testy funkcjonalne i wydajnościowe, w tym obciążeniowe i regresyjne) jest kluczowe dla zapewnienia, że baza danych działa zgodnie z wymaganiami i jest gotowa do użycia | F115: Imię03 | G115: ACT | H115: 4 | I115: .a03 | J115: 9 | K115: 46260 | L115: 46261 | M115: 9 | N115: 1 | O115: 200 | P115: 0.11 | Q115: 0.11 | R115: 0.11 | S115: 0.11 | T115: 0.11 | U115: 0.11 | V115: 0.11 | W115: 0.11 | X115: 0.12 | Y115: 0 | Z115: 0 | AA115: 0 | AB115: 0 | AC115: 0 | AD115: 0 | AE115: 0 | AF115: 0 | AG115: 22 | AH115: 22 | AI115: 22 | AJ115: 22 | AK115: 22 | AL115: 22 | AM115: 22 | AN115: 22 | AO115: 24 | AP115: 0 | AQ115: 0 | AR115: 0 | AS115: 0 | AT115: 0 | AU115: 0 | AV115: 0 | AW115: 0 | AX115: 200 | AY115: 1.25 | AZ115: 5003 | BA115: 6253.75 | BB115: 7817.1875 | BC115: 0 | BD115: 0 | BE115: 0 | BF115: 0 | BG115: 0 | BH115: 0 | BI115: 0 | BJ115: 200 | BK115: 200 | BL115: 0
A116: 2 | B116: b | C116: 1 | D116: .z01_2_b_1 | E116: Wybór platformy bazodanowej na podstawie testów wydajnościowych WBD | F116: Imię01 | G116: ACT | H116: 4 | I116: .a01 | J116: 10 | K116: 46267 | L116: 46267 | M116: 9 | N116: 0 | O116: 45 | P116: 0.11 | Q116: 0.11 | R116: 0.11 | S116: 0.11 | T116: 0.11 | U116: 0.11 | V116: 0.11 | W116: 0.11 | X116: 0.12 | Y116: 0 | Z116: 0 | AA116: 0 | AB116: 0 | AC116: 0 | AD116: 0 | AE116: 0 | AF116: 0 | AG116: 5 | AH116: 5 | AI116: 5 | AJ116: 5 | AK116: 5 | AL116: 5 | AM116: 5 | AN116: 5 | AO116: 5 | AP116: 0 | AQ116: 0 | AR116: 0 | AS116: 0 | AT116: 0 | AU116: 0 | AV116: 0 | AW116: 0 | AX116: 45 | AY116: 0.28125 | AZ116: 5001 | BA116: 1406.5312 | BB116: 395.58691 | BC116: 0 | BD116: 0 | BE116: 0 | BF116: 0 | BG116: 0 | BH116: 0 | BI116: 0 | BJ116: 45 | BK116: 45 | BL116: 0
A117: 2 | B117: c | C117: 1 | D117: .z01_2_c_1 | E117: Wybór odpowiedniej platformy technologicznej zapewniającej skalowalność, bezpieczeństwo i wydajność analiz AI/ML | F117: Imię03 | G117: ACT | H117: 4 | I117: .a03 | J117: 10 | K117: 46267 | L117: 46268 | M117: 10 | N117: 1 | O117: 200 | P117: 0.11 | Q117: 0.11 | R117: 0.11 | S117: 0.11 | T117: 0.11 | U117: 0.11 | V117: 0.11 | W117: 0.11 | X117: 0.12 | Y117: 0 | Z117: 0 | AA117: 0 | AB117: 0 | AC117: 0 | AD117: 0 | AE117: 0 | AF117: 0 | AG117: 22 | AH117: 22 | AI117: 22 | AJ117: 22 | AK117: 22 | AL117: 22 | AM117: 22 | AN117: 22 | AO117: 24 | AP117: 0 | AQ117: 0 | AR117: 0 | AS117: 0 | AT117: 0 | AU117: 0 | AV117: 0 | AW117: 0 | AX117: 200 | AY117: 1.25 | AZ117: 5003 | BA117: 6253.75 | BB117: 7817.1875 | BC117: 0 | BD117: 0 | BE117: 0 | BF117: 0 | BG117: 0 | BH117: 0 | BI117: 0 | BJ117: 200 | BK117: 200 | BL117: 0
A118: 2 | B118: d | C118: 1 | D118: .z01_2_d_1 | E118: Fizyczna implementacja WBD w infrastrukturze Wnioskodawcy | F118: Imię05 | G118: ACT | H118: 5 | I118: .a05 | J118: 11 | K118: 46274 | L118: 46276 | M118: 12 | N118: 2 | O118: 200 | P118: 0.2 | Q118: 0.2 | R118: 0.2 | S118: 0.2 | T118: 0.2 | U118: 0 | V118: 0 | W118: 0 | X118: 0 | Y118: 0 | Z118: 0 | AA118: 0 | AB118: 0 | AC118: 0 | AD118: 0 | AE118: 0 | AF118: 0 | AG118: 40 | AH118: 40 | AI118: 40 | AJ118: 40 | AK118: 40 | AL118: 0 | AM118: 0 | AN118: 0 | AO118: 0 | AP118: 0 | AQ118: 0 | AR118: 0 | AS118: 0 | AT118: 0 | AU118: 0 | AV118: 0 | AW118: 0 | AX118: 200 | AY118: 1.25 | AZ118: 5005 | BA118: 6256.25 | BB118: 7820.3125 | BC118: 0 | BD118: 0 | BE118: 0 | BF118: 0 | BG118: 0 | BH118: 0 | BI118: 0 | BJ118: 200 | BK118: 200 | BL118: 0
A119: 2 | B119: e | C119: 1 | D119: .z01_2_e_1 | E119: Utworzenie mechanizmu do transferu danych między infrastrukturą Wnioskodawcy a platformami technologicznymi (np. Google Cloud, Microsoft Azure, NVidia AI) | F119: Imię02 | G119: ACT/END | H119: 5 | I119: .a02 | J119: 13 | K119: 46288 | L119: 46288 | M119: 12 | N119: 0 | O119: 200 | P119: 0 | Q119: 0 | R119: 0 | S119: 0 | T119: 0 | U119: 0.15 | V119: 0.15 | W119: 0.15 | X119: 0.15 | Y119: 0.4 | Z119: 0 | AA119: 0 | AB119: 0 | AC119: 0 | AD119: 0 | AE119: 0 | AF119: 0 | AG119: 0 | AH119: 0 | AI119: 0 | AJ119: 0 | AK119: 0 | AL119: 30 | AM119: 30 | AN119: 30 | AO119: 30 | AP119: 80 | AQ119: 0 | AR119: 0 | AS119: 0 | AT119: 0 | AU119: 0 | AV119: 0 | AW119: 0 | AX119: 120 | AY119: 0.75 | AZ119: 5002 | BA119: 3751.5 | BB119: 2813.625 | BC119: 0 | BD119: 0 | BE119: 0 | BF119: 0 | BG119: 0 | BH119: 0 | BI119: 0 | BJ119: 200 | BK119: 200 | BL119: 0
A120: 3 | B120: a | C120: 1 | D120: .z01_3_a_1 | E120: 3.Opracowanie narzędzi do automatycznego monitorowania, wykrywających anomalie i nieprawidłowości w danych w czasie rzeczywistym, współpracujących z wybraną platformą bazodanową, przeprowadzających automatyczne sprawdzanie kompletności rekordów. Flagowane będą rekordy z brakującymi danymi natychmiast po ich wprowadzeniu/aktualizacji i wysyłane powiadomienia do administratorów, gdy liczba tych rekordów przekroczy próg 10 rekordów. Będą śledzić czas ostatniej aktualizacji każdego rekordu, flagując te, które nie były aktualizowane zgodnie z ustalonym harmonogramem (co 24h i generować odpowiednie alerty. | F120: Imię01 | G120: ACT | H120: 6 | I120: .a01 | J120: 13 | K120: 46288 | L120: 46290 | M120: 14 | N120: 2 | O120: 80 | P120: 0.5 | Q120: 0.5 | R120: 0 | S120: 0 | T120: 0 | U120: 0 | V120: 0 | W120: 0 | X120: 0 | Y120: 0 | Z120: 0 | AA120: 0 | AB120: 0 | AC120: 0 | AD120: 0 | AE120: 0 | AF120: 0 | AG120: 40 | AH120: 40 | AI120: 0 | AJ120: 0 | AK120: 0 | AL120: 0 | AM120: 0 | AN120: 0 | AO120: 0 | AP120: 0 | AQ120: 0 | AR120: 0 | AS120: 0 | AT120: 0 | AU120: 0 | AV120: 0 | AW120: 0 | AX120: 80 | AY120: 0.5 | AZ120: 5001 | BA120: 2500.5 | BB120: 1250.25 | BC120: 0 | BD120: 0 | BE120: 0 | BF120: 0 | BG120: 0 | BH120: 0 | BI120: 0 | BJ120: 80 | BK120: 80 | BL120: 0
A121: 4 | B121: a | C121: 0 | D121: .z01_4_a_0 | E121: 4.Połączenie WBD z wybranym systemem AI/ML, co pozwoli na zbadanie potencjału zaawansowanych metod analitycznych AI/ML w celu zwiększenia wydajności procesów magazynowych. | F121: 0 | G121: 0 | H121: 0 | I121: 0 | J121: 15 | K121: 46302 | L121: 46302 | M121: 14 | N121: 0 | O121: 0 | P121: 0 | Q121: 0 | R121: 0 | S121: 0 | T121: 0 | U121: 0 | V121: 0 | W121: 0 | X121: 0 | Y121: 0 | Z121: 0 | AA121: 0 | AB121: 0 | AC121: 0 | AD121: 0 | AE121: 0 | AF121: 0 | AG121: 0 | AH121: 0 | AI121: 0 | AJ121: 0 | AK121: 0 | AL121: 0 | AM121: 0 | AN121: 0 | AO121: 0 | AP121: 0 | AQ121: 0 | AR121: 0 | AS121: 0 | AT121: 0 | AU121: 0 | AV121: 0 | AW121: 0 | AX121: 0 | AY121: 0 | AZ121: 0 | BA121: 0 | BB121: 0 | BC121: 0 | BD121: 0 | BE121: 0 | BF121: 0 | BG121: 0 | BH121: 0 | BI121: 0 | BJ121: 0 | BK121: 0 | BL121: 0
A122: 4 | B122: a | C122: 1 | D122: .z01_4_a_1 | E122: Zaimportowanie WBD w środowisku wybranej platformy AI/ML | F122: Imię03 | G122: ACT | H122: 6 | I122: .a03 | J122: 15 | K122: 46302 | L122: 46302 | M122: 14 | N122: 0 | O122: 45 | P122: 0 | Q122: 0 | R122: 0.17 | S122: 0.14 | T122: 0.11 | U122: 0.14 | V122: 0.14 | W122: 0.15 | X122: 0.15 | Y122: 0 | Z122: 0 | AA122: 0 | AB122: 0 | AC122: 0 | AD122: 0 | AE122: 0 | AF122: 0 | AG122: 0 | AH122: 0 | AI122: 8 | AJ122: 6 | AK122: 5 | AL122: 6 | AM122: 6 | AN122: 7 | AO122: 7 | AP122: 0 | AQ122: 0 | AR122: 0 | AS122: 0 | AT122: 0 | AU122: 0 | AV122: 0 | AW122: 0 | AX122: 45 | AY122: 0.28125 | AZ122: 5003 | BA122: 1407.0938 | BB122: 395.74512 | BC122: 0 | BD122: 0 | BE122: 0 | BF122: 0 | BG122: 0 | BH122: 0 | BI122: 0 | BJ122: 45 | BK122: 45 | BL122: 0
A123: 4 | B123: b | C123: 1 | D123: .z01_4_b_1 | E123: Sprawdzenie i potwierdzenie poprawności zaimplementowanych danych. Określenie zestawu danych testowych i referencyjnych do dalszych analiz | F123: Imię01 | G123: ACT | H123: 6 | I123: .a01 | J123: 15 | K123: 46302 | L123: 46302 | M123: 14 | N123: 0 | O123: 45 | P123: 0 | Q123: 0 | R123: 0.17 | S123: 0.16 | T123: 0.16 | U123: 0.17 | V123: 0.17 | W123: 0.17 | X123: 0 | Y123: 0 | Z123: 0 | AA123: 0 | AB123: 0 | AC123: 0 | AD123: 0 | AE123: 0 | AF123: 0 | AG123: 0 | AH123: 0 | AI123: 8 | AJ123: 7 | AK123: 7 | AL123: 8 | AM123: 8 | AN123: 8 | AO123: 0 | AP123: 0 | AQ123: 0 | AR123: 0 | AS123: 0 | AT123: 0 | AU123: 0 | AV123: 0 | AW123: 0 | AX123: 46 | AY123: 0.2875 | AZ123: 5001 | BA123: 1437.7875 | BB123: 413.36391 | BC123: 0 | BD123: 0 | BE123: 0 | BF123: 0 | BG123: 0 | BH123: 0 | BI123: 0 | BJ123: 45 | BK123: 46 | BL123: -1
A124: 4 | B124: c | C124: 1 | D124: .z01_4_c_1 | E124: Stworzenie zautomatyzowanego systemu aktualizacji danych WBD zintegrowanej z platformą. | F124: Imię02 | G124: ACT | H124: 6 | I124: .a02 | J124: 15 | K124: 46302 | L124: 46303 | M124: 15 | N124: 1 | O124: 80 | P124: 0 | Q124: 0 | R124: 0 | S124: 0.16 | T124: 0.16 | U124: 0.17 | V124: 0.17 | W124: 0.17 | X124: 0.17 | Y124: 0 | Z124: 0 | AA124: 0 | AB124: 0 | AC124: 0 | AD124: 0 | AE124: 0 | AF124: 0 | AG124: 0 | AH124: 0 | AI124: 0 | AJ124: 13 | AK124: 13 | AL124: 14 | AM124: 14 | AN124: 14 | AO124: 14 | AP124: 0 | AQ124: 0 | AR124: 0 | AS124: 0 | AT124: 0 | AU124: 0 | AV124: 0 | AW124: 0 | AX124: 82 | AY124: 0.5125 | AZ124: 5002 | BA124: 2563.525 | BB124: 1313.8066 | BC124: 0 | BD124: 0 | BE124: 0 | BF124: 0 | BG124: 0 | BH124: 0 | BI124: 0 | BJ124: 80 | BK124: 82 | BL124: -2
A125: 5 | B125: a | C125: 1 | D125: .z01_5_a_1 | E125: 5.Opracowanie procedur/strategii bezpieczeństwa i zarządzania WBD | F125: Imię03 | G125: ACT | H125: 7 | I125: .a03 | J125: 16 | K125: 46309 | L125: 46310 | M125: 16 | N125: 1 | O125: 80 | P125: 0.11 | Q125: 0.11 | R125: 0.11 | S125: 0.11 | T125: 0.11 | U125: 0.11 | V125: 0.11 | W125: 0.11 | X125: 0.12 | Y125: 0 | Z125: 0 | AA125: 0 | AB125: 0 | AC125: 0 | AD125: 0 | AE125: 0 | AF125: 0 | AG125: 9 | AH125: 9 | AI125: 9 | AJ125: 9 | AK125: 9 | AL125: 9 | AM125: 9 | AN125: 9 | AO125: 10 | AP125: 0 | AQ125: 0 | AR125: 0 | AS125: 0 | AT125: 0 | AU125: 0 | AV125: 0 | AW125: 0 | AX125: 82 | AY125: 0.5125 | AZ125: 5003 | BA125: 2564.0375 | BB125: 1314.0692 | BC125: 0 | BD125: 0 | BE125: 0 | BF125: 0 | BG125: 0 | BH125: 0 | BI125: 0 | BJ125: 80 | BK125: 82 | BL125: -2
...

Sheet Listy
A1: .a01 | B1: Imię01 | C1: Nazwisko01 | D1: Janusz Strzelecki | E1: =ROUND(F1*H1*G1,2) | F1: 5001 | G1: 0.5 | H1: 1.43 | J1: Arkusz zablokowany - bez hasła | P1: KodZatr | Q1: Lp. | R1: Imię i nazwisko | S1: Typ zatrudnienia | T1: ilość godzin per m-c | U1: ilość godzin per Tyg. | V1: rola1 | AA1: T= | AB1: h=
A2: .a02 | B2: Imię02 | C2: Nazwisko02 | D2: Mariusz Cegliński | E2: =ROUND(F2*H2*G2,2) | F2: 5002 | G2: 0.5 | H2: 1.43 | P2: .b01 | Q2: 1. | R2: Janusz Strzelecki | S2: B2B | T2: 80 | U2: =T2/4 | V2: Analityk/Programista | X2: ACT Analityk Danych01
A3: .a03 | B3: Imię03 | C3: Nazwisko03 | D3: Wojciech Mazur | E3: =ROUND(F3*H3*G3,2) | F3: 5003 | G3: 0.5 | H3: 1.43 | P3: .b02 | Q3: 2. | R3: Mariusz Cegliński | S3: B2B | T3: 80 | U3: =T3/4 | V3: Analityk/Programista | X3: ACT Analityk Danych02
A4: .a04 | B4: Imię04 | C4: Nazwisko04 | D4: Tomasz Grzegorek | E4: =ROUND(F4*H4*G4,2) | F4: 5004 | G4: 0.5 | H4: 1.43 | P4: .b03 | Q4: 3. | R4: Wojciech Mazur | S4: UP | T4: 80 | U4: =T4/4 | V4: Analityk/Programista | X4: ACT Analityk Danych03
A5: .a05 | B5: Imię05 | C5: Nazwisko05 | D5: Sebastian Kaczmar | E5: =ROUND(F5*H5*G5,2) | F5: 5005 | G5: 0.5 | H5: 1.43 | Q5: 4. | R5: Tomasz Grzegorek | S5: UP | T5: 80 | U5: =T5/4 | V5: Analityk/Programista | X5: ACT Analityk Danych04
A6: .a06 | B6: Imię06 | C6: Nazwisko06 | D6: Dorota Duży | E6: =ROUND(F6*H6*G6,2) | F6: 5006 | G6: 0.5 | H6: 1.43 | Q6: 5. | R6: Sebastian Kaczmar | S6: UP | T6: 80 | U6: =T6/4 | X6: ACT Analityk Danych05
A7: .a07 | B7: Imię07 | C7: Nazwisko07 | D7: Dariusz Gąsior | E7: =ROUND(F7*H7*G7,2) | F7: 5007 | G7: 0.5 | H7: 1.43 | Q7: 6. | R7: Dorota Duży | S7: UP | T7: 80 | U7: =T7/4 | X7: ACT Analityk Danych06
A8: .a08 | B8: Imię08 | C8: Nazwisko08 | D8: Prog_8 | E8: =ROUND(F8*H8*G8,2) | F8: 5008 | G8: 0.5 | H8: 1.43 | Q8: 7. | R8: Dariusz Gąsior | S8: B2B/Kontrakt men. | T8: 80 | U8: =T8/4 | V8: Analityk/Programista | X8: ACT Analityk Danych07
A9: .a09 | B9: Imię09 | C9: Nazwisko09 | D9: Prog_9 | E9: =ROUND(F9*H9*G9,2) | F9: 5009 | G9: 0.5 | H9: 1.43 | Q9: 8. | R9: Prog_8 | T9: 80 | U9: =T9/4 | X9: ACT Analityk Danych08
A10: B_2_B Action | B10: Firma | D10: Rola w projekcie | E10: Netto | Q10: 9. | R10: Prog_9 | T10: 80 | U10: =T10/4 | X10: ACT Analityk Danych09
A11: .b01 | B11: B2B_Janusz
A12: .b02 | B12: B2B_Mariusz | Q12: 10. | R12: Andrzej Walasek | T12: 20 | U12: =T12/4
A13: .b03 | B13: B2B_Dariusz | Q13: 11. | R13: Włodzimierz Ossowski | T13: 10 | U13: =T13/4
A14: .b04 | B14: B2B_4 | Q14: 12. | R14: Obsada magazynu | S14: UP | T14: prace weekendowe | V14: W trakcie testów/ilość osób do ustalenia z Sebastianem Stępniewskim
A15: .b05 | B15: B2B_5 | Q15: 13. | R15: Sebastian Stępniewski | S15: UP | T15: 10 | U15: =T15/4
A16: .b06 | B16: B2B_6
A17: .b07 | B17: B2B_7 | S17: UP
A18: .b08 | B18: B2B_8 | S18: UP
A19: .b09 | B19: B2B_9
A20: ENDAWA | B20: Firma | D20: Rola w projekcie | E20: Netto | T20: 176 | U20: średnia ilość godzin w miesiącu
A21: .e01 | B21: ENDAWA_01 | D21: END Analityk Danych/ Inżynier ML 1 | T21: 40 | U21: =T20/T21
A22: .e02 | B22: ENDAWA_02 | D22: END Analityk Danych/ Inżynier ML 2
A23: .e03 | B23: ENDAWA_03 | D23: END Analityk Danych/ Inżynier ML 3
A24: .e04 | B24: ENDAWA_04 | D24: END Inż. Automatyzacji | Q24: 1 | S24: =Q24*6
A25: .e05 | B25: ENDAWA_05 | D25: Analityk_END_05 | Q25: 2 | S25: =Q25*6
A26: .e06 | B26: ENDAWA_06 | D26: Analityk_END_06 | Q26: 3 | S26: =Q26*6
A27: .e07 | B27: ENDAWA_07 | D27: Analityk_END_07 | Q27: 4 | S27: =Q27*6
A28: .e08 | B28: ENDAWA_08 | D28: Analityk_END_08 | Q28: 5 | R28: =U$2*Q28 | S28: =Q28*6
A29: .e09 | B29: ENDAWA_09 | D29: Analityk_END_09 | Q29: 6 | R29: =U$2*Q29 | S29: =Q29*6
A30: AGH Kraków | B30: Firma | D30: Rola w projekcie | E30: Netto | Q30: 7 | R30: =U$2*Q30 | S30: =Q30*6
A31: .g01 | B31: AGH_01 | D31: AGH - Profesor (max 50% etatu) | Q31: 8 | R31: =U$2*Q31 | S31: =Q31*6
A32: .g02 | B32: AGH_02 | D32: AGH - Pracownik naukowy 1 (max 50% etatu) | Q32: 9 | R32: =U$2*Q32 | S32: =Q32*6
A33: .g03 | B33: AGH_03 | D33: AGH Pracownik nukowy 2 (max 50% etatu) | Q33: 10 | R33: =U$2*Q33
A34: .g04 | B34: AGH_04 | D34: AGH Pracownik naukowy 3 (max 50% etatu) | Q34: 11
A35: .g05 | B35: AGH_05 | D35: Analityk_AGH_05
A36: .g06 | B36: AGH_06 | D36: Analityk_AGH_06
A37: .g07 | B37: AGH_07 | D37: Analityk_AGH_07
A38: .g08 | B38: AGH_08 | D38: Analityk_AGH_08
A39: .g09 | B39: AGH_09 | D39: Analityk_AGH_09
A71: ZADANIA GŁÓWNE | C71: aktualne | K71: =Karta!M2 | L71: =Karta!N2 | M71: =Karta!O2 | W71: było
...

Sheet Schemat
A1: Schemat | C1: OsobyACT=9 | K1: 46388 | L1: Start | O1: Ochrona bez hasła
E2: 10
B3: OsobyACT=4 | E3: 11 | H3: 11 | K3: OsobyACT=5
B4: T=9 | H4: 16 | K4: T=6 | N4: Warunek:
E5: 19 | N5: Program musi zakończyć się we wrześniu 2029 bez względu kiedy się zacznie !!!
H6: 17
B7: =$B$3 | E7: 20 | K7: =$K$3
B8: T=20 | E8: 39 | K8: T=32
B10: =$B$3 | E10: 40 | H10: 48
B11: T=10 | E11: 49
H12: 49 | K12: =$K$3
E13: 50 | H13: 55 | K13: T=7
B14: =$B$3
B15: T=37 | H15: 56
E17: 86 | K17: =$K$3
H18: 97 | K18: T=42
E19: 87
C20: OsobyACT=6
C21: T=42
E22: 128
D23: OsobyACT=6
D24: T=14 | I24: 142 | K24: 47389 | L24: The End :)

Sheet I_Wzorcowa_BD
E1: HARMONOGRAM SKOMPRESOWANY v1 | 01.01.2027 – 28.09.2029 | Kompresja −40% per zadanie | Endava +5 etatów | AGH +4 etatów | J1: 1 | M1: =MAX(M3:M9999) | N1: =SUM(N$4:N$999) | O1: =SUM(O$4:O$999) | P1: =AG1 | Q1: =AH1 | R1: =AI1 | S1: =AJ1 | T1: =AK1 | U1: =AL1 | V1: =AM1 | W1: =AN1 | ... AF1: =AW1 | AG1: =Listy!$AB$1 & MAX(AG$3:AG99) | AH1: =Listy!$AB$1 & MAX(AH$3:AH99) | AI1: =Listy!$AB$1 & MAX(AI$3:AI99) | AJ1: =Listy!$AB$1 & MAX(AJ$3:AJ99) | AK1: =Listy!$AB$1 & MAX(AK$3:AK99) | AL1: =Listy!$AB$1 & MAX(AL$3:AL99) | AM1: =Listy!$AB$1 & MAX(AM$3:AM99) | AN1: =Listy!$AB$1 & MAX(AN$3:AN99) | ... AW1: =Listy!$AB$1 & MAX(AW$3:AW99)
A2: =Karta!A2 | B2: =Karta!B2 | C2: =Karta!C2 | D2: =Karta!D2 | E2: =Karta!E2 | F2: =Karta!F2 | G2: =Karta!G2 | H2: =Karta!H2 | ... AB2: =Karta!AB2 | AC2: =Karta!AG2 | AD2: =Karta!AH2 | AE2: =Karta!AI2 | AF2: =Karta!AJ2 | AG2: =Karta!AL2 | AH2: =Karta!AM2 | AI2: =Karta!AN2 | AJ2: =Karta!AO2 | AK2: =Karta!AP2 | AL2: =Karta!AQ2 | AM2: =Karta!AR2 | AN2: =Karta!AS2 | ... AS2: =Karta!AX2 | AT2: =Karta!BC2 | AU2: =Karta!BD2 | AV2: =Karta!BE2 | AW2: =Karta!BF2 | AX2: =Karta!BH2 | AY2: =Karta!BI2 | AZ2: =Karta!BJ2 | BA2: =Karta!BK2 | BB2: =Karta!BL2 | BC2: =Karta!BM2 | BD2: =Karta!BN2 | BE2: =Karta!BO2 | ... CE2: =Karta!CO2
A3: .z01 | E3: =VLOOKUP(A3,Listy!A:C,2,FALSE) & " : " & VLOOKUP(A3,Listy!A:C,3,FALSE)
A4: 1 | B4: a | C4: -1 | D4: =CONCATENATE(A$3,"_",A4,"_",B4,"_",C4) | E4: 1.Opracowanie koncepcji standaryzowanej wzorcowej bazy danych | G4: ACT | I4: ACT
A5: 1 | B5: a | C5: 0 | D5: =CONCATENATE(A$3,"_",A5,"_",B5,"_",C5) | E5: 1.a.Projektowanie struktury bazy danych, która zapewni jej wydajność, spójność i skalowalność | J5: 1 | K5: =VLOOKUP(J5,Kalendarz!B:E,4,FALSE) | L5: =K5+N5 | M5: =J5+N5-1 | N5: 0
A6: 1 | B6: a | C6: 1 | D6: =CONCATENATE(A$3,"_",A6,"_",B6,"_",C6) | E6: Opracowanie logicznego i fizycznego modelu bazy danych, uwzględniającego wszystkie kluczowe elementy (np. tabele, relacje, indeksy i klucze) | F6: =IFERROR(VLOOKUP($I6,Listy!$A:$H,2,FALSE),"XXX") | G6: ACT | H6: 1 | I6: .a02 | J6: =M5+1 | K6: =VLOOKUP(J6,Kalendarz!B:E,4,FALSE) | L6: =K6+N6 | M6: =J6+N6-1 | N6: 1 | O6: 320 | P6: 0.25 | Q6: 0.25 | R6: 0.25 | S6: 0.25 | T6: 0 | U6: 0 | V6: 0 | W6: 0 | X6: 0 | Y6: 0 | Z6: 0 | AA6: 0 | AB6: 0 | AG6: =ROUND($O6*P6,0) | AH6: =ROUND($O6*Q6,0) | AI6: =ROUND($O6*R6,0) | AJ6: =ROUND($O6*S6,0) | AK6: =ROUND($O6*T6,0) | AL6: =ROUND($O6*U6,0) | AM6: =ROUND($O6*V6,0) | AN6: =ROUND($O6*W6,0) | ... AW6: =ROUND($O6*AF6,0) | AX6: =SUM(AG6:AO6) | AY6: =AX6/160 | AZ6: =VLOOKUP(I6,Listy!$A$1:$H$9,6,FALSE) | BA6: =AY6*AZ6 | BB6: =AY6*BA6 | BI6: =BG6*BH6 | BW6: =BU6*BV6 | CA6: =BY6*BZ6 | CE6: =CC6*CD6
